[2021-04-26 16:31:16.773 DEBUG                    django.template : 878]
Exception while resolving variable 'min' in template 'ysdevices/device_form.html'.
Traceback (most recent call last):
  File "/home/nsindiso/.local/lib/python3.6/site-packages/django/template/base.py", line 835, in _resolve_lookup
    current = current[bit]
KeyError: 'min'

During handling of the above exception, another exception occurred:

Traceback (most recent call last):
  File "/home/nsindiso/.local/lib/python3.6/site-packages/django/template/base.py", line 843, in _resolve_lookup
    current = getattr(current, bit)
AttributeError: 'dict' object has no attribute 'min'

During handling of the above exception, another exception occurred:

Traceback (most recent call last):
  File "/home/nsindiso/.local/lib/python3.6/site-packages/django/template/base.py", line 849, in _resolve_lookup
    current = current[int(bit)]
ValueError: invalid literal for int() with base 10: 'min'

During handling of the above exception, another exception occurred:

Traceback (most recent call last):
  File "/home/nsindiso/.local/lib/python3.6/site-packages/django/template/base.py", line 856, in _resolve_lookup
    (bit, current))  # missing attribute
django.template.base.VariableDoesNotExist: Failed lookup for key [min] in {'label': 'Profile Name', 'type': 'string', 'description': 'Name of this device profile', 'minLength': 1, 'required': True, 'default': 'CSR100V'}
[2021-04-26 16:31:16.780 DEBUG                    django.template : 878]
Exception while resolving variable 'max' in template 'ysdevices/device_form.html'.
Traceback (most recent call last):
  File "/home/nsindiso/.local/lib/python3.6/site-packages/django/template/base.py", line 835, in _resolve_lookup
    current = current[bit]
KeyError: 'max'

During handling of the above exception, another exception occurred:

Traceback (most recent call last):
  File "/home/nsindiso/.local/lib/python3.6/site-packages/django/template/base.py", line 843, in _resolve_lookup
    current = getattr(current, bit)
AttributeError: 'dict' object has no attribute 'max'

During handling of the above exception, another exception occurred:

Traceback (most recent call last):
  File "/home/nsindiso/.local/lib/python3.6/site-packages/django/template/base.py", line 849, in _resolve_lookup
    current = current[int(bit)]
ValueError: invalid literal for int() with base 10: 'max'

During handling of the above exception, another exception occurred:

Traceback (most recent call last):
  File "/home/nsindiso/.local/lib/python3.6/site-packages/django/template/base.py", line 856, in _resolve_lookup
    (bit, current))  # missing attribute
django.template.base.VariableDoesNotExist: Failed lookup for key [max] in {'label': 'Profile Name', 'type': 'string', 'description': 'Name of this device profile', 'minLength': 1, 'required': True, 'default': 'CSR100V'}
[2021-04-26 16:31:16.781 DEBUG                    django.template : 878]
Exception while resolving variable 'maxLength' in template 'ysdevices/device_form.html'.
Traceback (most recent call last):
  File "/home/nsindiso/.local/lib/python3.6/site-packages/django/template/base.py", line 835, in _resolve_lookup
    current = current[bit]
KeyError: 'maxLength'

During handling of the above exception, another exception occurred:

Traceback (most recent call last):
  File "/home/nsindiso/.local/lib/python3.6/site-packages/django/template/base.py", line 843, in _resolve_lookup
    current = getattr(current, bit)
AttributeError: 'dict' object has no attribute 'maxLength'

During handling of the above exception, another exception occurred:

Traceback (most recent call last):
  File "/home/nsindiso/.local/lib/python3.6/site-packages/django/template/base.py", line 849, in _resolve_lookup
    current = current[int(bit)]
ValueError: invalid literal for int() with base 10: 'maxLength'

During handling of the above exception, another exception occurred:

Traceback (most recent call last):
  File "/home/nsindiso/.local/lib/python3.6/site-packages/django/template/base.py", line 856, in _resolve_lookup
    (bit, current))  # missing attribute
django.template.base.VariableDoesNotExist: Failed lookup for key [maxLength] in {'label': 'Profile Name', 'type': 'string', 'description': 'Name of this device profile', 'minLength': 1, 'required': True, 'default': 'CSR100V'}
[2021-04-26 16:31:16.782 DEBUG                    django.template : 878]
Exception while resolving variable 'step' in template 'ysdevices/device_form.html'.
Traceback (most recent call last):
  File "/home/nsindiso/.local/lib/python3.6/site-packages/django/template/base.py", line 835, in _resolve_lookup
    current = current[bit]
KeyError: 'step'

During handling of the above exception, another exception occurred:

Traceback (most recent call last):
  File "/home/nsindiso/.local/lib/python3.6/site-packages/django/template/base.py", line 843, in _resolve_lookup
    current = getattr(current, bit)
AttributeError: 'dict' object has no attribute 'step'

During handling of the above exception, another exception occurred:

Traceback (most recent call last):
  File "/home/nsindiso/.local/lib/python3.6/site-packages/django/template/base.py", line 849, in _resolve_lookup
    current = current[int(bit)]
ValueError: invalid literal for int() with base 10: 'step'

During handling of the above exception, another exception occurred:

Traceback (most recent call last):
  File "/home/nsindiso/.local/lib/python3.6/site-packages/django/template/base.py", line 856, in _resolve_lookup
    (bit, current))  # missing attribute
django.template.base.VariableDoesNotExist: Failed lookup for key [step] in {'label': 'Profile Name', 'type': 'string', 'description': 'Name of this device profile', 'minLength': 1, 'required': True, 'default': 'CSR100V'}
[2021-04-26 16:31:16.783 DEBUG                    django.template : 878]
Exception while resolving variable 'min' in template 'ysdevices/device_form.html'.
Traceback (most recent call last):
  File "/home/nsindiso/.local/lib/python3.6/site-packages/django/template/base.py", line 835, in _resolve_lookup
    current = current[bit]
KeyError: 'min'

During handling of the above exception, another exception occurred:

Traceback (most recent call last):
  File "/home/nsindiso/.local/lib/python3.6/site-packages/django/template/base.py", line 843, in _resolve_lookup
    current = getattr(current, bit)
AttributeError: 'dict' object has no attribute 'min'

During handling of the above exception, another exception occurred:

Traceback (most recent call last):
  File "/home/nsindiso/.local/lib/python3.6/site-packages/django/template/base.py", line 849, in _resolve_lookup
    current = current[int(bit)]
ValueError: invalid literal for int() with base 10: 'min'

During handling of the above exception, another exception occurred:

Traceback (most recent call last):
  File "/home/nsindiso/.local/lib/python3.6/site-packages/django/template/base.py", line 856, in _resolve_lookup
    (bit, current))  # missing attribute
django.template.base.VariableDoesNotExist: Failed lookup for key [min] in {'type': 'string', 'description': 'Verbose description', 'default': 'MDT'}
[2021-04-26 16:31:16.784 DEBUG                    django.template : 878]
Exception while resolving variable 'minLength' in template 'ysdevices/device_form.html'.
Traceback (most recent call last):
  File "/home/nsindiso/.local/lib/python3.6/site-packages/django/template/base.py", line 835, in _resolve_lookup
    current = current[bit]
KeyError: 'minLength'

During handling of the above exception, another exception occurred:

Traceback (most recent call last):
  File "/home/nsindiso/.local/lib/python3.6/site-packages/django/template/base.py", line 843, in _resolve_lookup
    current = getattr(current, bit)
AttributeError: 'dict' object has no attribute 'minLength'

During handling of the above exception, another exception occurred:

Traceback (most recent call last):
  File "/home/nsindiso/.local/lib/python3.6/site-packages/django/template/base.py", line 849, in _resolve_lookup
    current = current[int(bit)]
ValueError: invalid literal for int() with base 10: 'minLength'

During handling of the above exception, another exception occurred:

Traceback (most recent call last):
  File "/home/nsindiso/.local/lib/python3.6/site-packages/django/template/base.py", line 856, in _resolve_lookup
    (bit, current))  # missing attribute
django.template.base.VariableDoesNotExist: Failed lookup for key [minLength] in {'type': 'string', 'description': 'Verbose description', 'default': 'MDT'}
[2021-04-26 16:31:16.785 DEBUG                    django.template : 878]
Exception while resolving variable 'max' in template 'ysdevices/device_form.html'.
Traceback (most recent call last):
  File "/home/nsindiso/.local/lib/python3.6/site-packages/django/template/base.py", line 835, in _resolve_lookup
    current = current[bit]
KeyError: 'max'

During handling of the above exception, another exception occurred:

Traceback (most recent call last):
  File "/home/nsindiso/.local/lib/python3.6/site-packages/django/template/base.py", line 843, in _resolve_lookup
    current = getattr(current, bit)
AttributeError: 'dict' object has no attribute 'max'

During handling of the above exception, another exception occurred:

Traceback (most recent call last):
  File "/home/nsindiso/.local/lib/python3.6/site-packages/django/template/base.py", line 849, in _resolve_lookup
    current = current[int(bit)]
ValueError: invalid literal for int() with base 10: 'max'

During handling of the above exception, another exception occurred:

Traceback (most recent call last):
  File "/home/nsindiso/.local/lib/python3.6/site-packages/django/template/base.py", line 856, in _resolve_lookup
    (bit, current))  # missing attribute
django.template.base.VariableDoesNotExist: Failed lookup for key [max] in {'type': 'string', 'description': 'Verbose description', 'default': 'MDT'}
[2021-04-26 16:31:16.786 DEBUG                    django.template : 878]
Exception while resolving variable 'maxLength' in template 'ysdevices/device_form.html'.
Traceback (most recent call last):
  File "/home/nsindiso/.local/lib/python3.6/site-packages/django/template/base.py", line 835, in _resolve_lookup
    current = current[bit]
KeyError: 'maxLength'

During handling of the above exception, another exception occurred:

Traceback (most recent call last):
  File "/home/nsindiso/.local/lib/python3.6/site-packages/django/template/base.py", line 843, in _resolve_lookup
    current = getattr(current, bit)
AttributeError: 'dict' object has no attribute 'maxLength'

During handling of the above exception, another exception occurred:

Traceback (most recent call last):
  File "/home/nsindiso/.local/lib/python3.6/site-packages/django/template/base.py", line 849, in _resolve_lookup
    current = current[int(bit)]
ValueError: invalid literal for int() with base 10: 'maxLength'

During handling of the above exception, another exception occurred:

Traceback (most recent call last):
  File "/home/nsindiso/.local/lib/python3.6/site-packages/django/template/base.py", line 856, in _resolve_lookup
    (bit, current))  # missing attribute
django.template.base.VariableDoesNotExist: Failed lookup for key [maxLength] in {'type': 'string', 'description': 'Verbose description', 'default': 'MDT'}
[2021-04-26 16:31:16.787 DEBUG                    django.template : 878]
Exception while resolving variable 'step' in template 'ysdevices/device_form.html'.
Traceback (most recent call last):
  File "/home/nsindiso/.local/lib/python3.6/site-packages/django/template/base.py", line 835, in _resolve_lookup
    current = current[bit]
KeyError: 'step'

During handling of the above exception, another exception occurred:

Traceback (most recent call last):
  File "/home/nsindiso/.local/lib/python3.6/site-packages/django/template/base.py", line 843, in _resolve_lookup
    current = getattr(current, bit)
AttributeError: 'dict' object has no attribute 'step'

During handling of the above exception, another exception occurred:

Traceback (most recent call last):
  File "/home/nsindiso/.local/lib/python3.6/site-packages/django/template/base.py", line 849, in _resolve_lookup
    current = current[int(bit)]
ValueError: invalid literal for int() with base 10: 'step'

During handling of the above exception, another exception occurred:

Traceback (most recent call last):
  File "/home/nsindiso/.local/lib/python3.6/site-packages/django/template/base.py", line 856, in _resolve_lookup
    (bit, current))  # missing attribute
django.template.base.VariableDoesNotExist: Failed lookup for key [step] in {'type': 'string', 'description': 'Verbose description', 'default': 'MDT'}
[2021-04-26 16:31:16.787 DEBUG                    django.template : 878]
Exception while resolving variable 'required' in template 'ysdevices/device_form.html'.
Traceback (most recent call last):
  File "/home/nsindiso/.local/lib/python3.6/site-packages/django/template/base.py", line 835, in _resolve_lookup
    current = current[bit]
KeyError: 'required'

During handling of the above exception, another exception occurred:

Traceback (most recent call last):
  File "/home/nsindiso/.local/lib/python3.6/site-packages/django/template/base.py", line 843, in _resolve_lookup
    current = getattr(current, bit)
AttributeError: 'dict' object has no attribute 'required'

During handling of the above exception, another exception occurred:

Traceback (most recent call last):
  File "/home/nsindiso/.local/lib/python3.6/site-packages/django/template/base.py", line 849, in _resolve_lookup
    current = current[int(bit)]
ValueError: invalid literal for int() with base 10: 'required'

During handling of the above exception, another exception occurred:

Traceback (most recent call last):
  File "/home/nsindiso/.local/lib/python3.6/site-packages/django/template/base.py", line 856, in _resolve_lookup
    (bit, current))  # missing attribute
django.template.base.VariableDoesNotExist: Failed lookup for key [required] in {'type': 'string', 'description': 'Verbose description', 'default': 'MDT'}
[2021-04-26 16:31:16.788 DEBUG                    django.template : 878]
Exception while resolving variable 'label' in template 'ysdevices/device_form.html'.
Traceback (most recent call last):
  File "/home/nsindiso/.local/lib/python3.6/site-packages/django/template/base.py", line 835, in _resolve_lookup
    current = current[bit]
KeyError: 'label'

During handling of the above exception, another exception occurred:

Traceback (most recent call last):
  File "/home/nsindiso/.local/lib/python3.6/site-packages/django/template/base.py", line 843, in _resolve_lookup
    current = getattr(current, bit)
AttributeError: 'dict' object has no attribute 'label'

During handling of the above exception, another exception occurred:

Traceback (most recent call last):
  File "/home/nsindiso/.local/lib/python3.6/site-packages/django/template/base.py", line 849, in _resolve_lookup
    current = current[int(bit)]
ValueError: invalid literal for int() with base 10: 'label'

During handling of the above exception, another exception occurred:

Traceback (most recent call last):
  File "/home/nsindiso/.local/lib/python3.6/site-packages/django/template/base.py", line 856, in _resolve_lookup
    (bit, current))  # missing attribute
django.template.base.VariableDoesNotExist: Failed lookup for key [label] in {'type': 'string', 'description': 'Verbose description', 'default': 'MDT'}
[2021-04-26 16:31:16.790 DEBUG                    django.template : 878]
Exception while resolving variable 'required' in template 'ysdevices/device_form.html'.
Traceback (most recent call last):
  File "/home/nsindiso/.local/lib/python3.6/site-packages/django/template/base.py", line 835, in _resolve_lookup
    current = current[bit]
KeyError: 'required'

During handling of the above exception, another exception occurred:

Traceback (most recent call last):
  File "/home/nsindiso/.local/lib/python3.6/site-packages/django/template/base.py", line 843, in _resolve_lookup
    current = getattr(current, bit)
AttributeError: 'dict' object has no attribute 'required'

During handling of the above exception, another exception occurred:

Traceback (most recent call last):
  File "/home/nsindiso/.local/lib/python3.6/site-packages/django/template/base.py", line 849, in _resolve_lookup
    current = current[int(bit)]
ValueError: invalid literal for int() with base 10: 'required'

During handling of the above exception, another exception occurred:

Traceback (most recent call last):
  File "/home/nsindiso/.local/lib/python3.6/site-packages/django/template/base.py", line 856, in _resolve_lookup
    (bit, current))  # missing attribute
django.template.base.VariableDoesNotExist: Failed lookup for key [required] in {'type': 'string', 'description': 'Verbose description', 'default': 'MDT'}
[2021-04-26 16:31:16.791 DEBUG                    django.template : 878]
Exception while resolving variable 'min' in template 'ysdevices/device_form.html'.
Traceback (most recent call last):
  File "/home/nsindiso/.local/lib/python3.6/site-packages/django/template/base.py", line 835, in _resolve_lookup
    current = current[bit]
KeyError: 'min'

During handling of the above exception, another exception occurred:

Traceback (most recent call last):
  File "/home/nsindiso/.local/lib/python3.6/site-packages/django/template/base.py", line 843, in _resolve_lookup
    current = getattr(current, bit)
AttributeError: 'dict' object has no attribute 'min'

During handling of the above exception, another exception occurred:

Traceback (most recent call last):
  File "/home/nsindiso/.local/lib/python3.6/site-packages/django/template/base.py", line 849, in _resolve_lookup
    current = current[int(bit)]
ValueError: invalid literal for int() with base 10: 'min'

During handling of the above exception, another exception occurred:

Traceback (most recent call last):
  File "/home/nsindiso/.local/lib/python3.6/site-packages/django/template/base.py", line 856, in _resolve_lookup
    (bit, current))  # missing attribute
django.template.base.VariableDoesNotExist: Failed lookup for key [min] in {'type': 'string', 'description': 'Address or hostname to use as default for all protocols', 'required': True, 'default': '192.168.42.82'}
[2021-04-26 16:31:16.792 DEBUG                    django.template : 878]
Exception while resolving variable 'minLength' in template 'ysdevices/device_form.html'.
Traceback (most recent call last):
  File "/home/nsindiso/.local/lib/python3.6/site-packages/django/template/base.py", line 835, in _resolve_lookup
    current = current[bit]
KeyError: 'minLength'

During handling of the above exception, another exception occurred:

Traceback (most recent call last):
  File "/home/nsindiso/.local/lib/python3.6/site-packages/django/template/base.py", line 843, in _resolve_lookup
    current = getattr(current, bit)
AttributeError: 'dict' object has no attribute 'minLength'

During handling of the above exception, another exception occurred:

Traceback (most recent call last):
  File "/home/nsindiso/.local/lib/python3.6/site-packages/django/template/base.py", line 849, in _resolve_lookup
    current = current[int(bit)]
ValueError: invalid literal for int() with base 10: 'minLength'

During handling of the above exception, another exception occurred:

Traceback (most recent call last):
  File "/home/nsindiso/.local/lib/python3.6/site-packages/django/template/base.py", line 856, in _resolve_lookup
    (bit, current))  # missing attribute
django.template.base.VariableDoesNotExist: Failed lookup for key [minLength] in {'type': 'string', 'description': 'Address or hostname to use as default for all protocols', 'required': True, 'default': '192.168.42.82'}
[2021-04-26 16:31:16.793 DEBUG                    django.template : 878]
Exception while resolving variable 'max' in template 'ysdevices/device_form.html'.
Traceback (most recent call last):
  File "/home/nsindiso/.local/lib/python3.6/site-packages/django/template/base.py", line 835, in _resolve_lookup
    current = current[bit]
KeyError: 'max'

During handling of the above exception, another exception occurred:

Traceback (most recent call last):
  File "/home/nsindiso/.local/lib/python3.6/site-packages/django/template/base.py", line 843, in _resolve_lookup
    current = getattr(current, bit)
AttributeError: 'dict' object has no attribute 'max'

During handling of the above exception, another exception occurred:

Traceback (most recent call last):
  File "/home/nsindiso/.local/lib/python3.6/site-packages/django/template/base.py", line 849, in _resolve_lookup
    current = current[int(bit)]
ValueError: invalid literal for int() with base 10: 'max'

During handling of the above exception, another exception occurred:

Traceback (most recent call last):
  File "/home/nsindiso/.local/lib/python3.6/site-packages/django/template/base.py", line 856, in _resolve_lookup
    (bit, current))  # missing attribute
django.template.base.VariableDoesNotExist: Failed lookup for key [max] in {'type': 'string', 'description': 'Address or hostname to use as default for all protocols', 'required': True, 'default': '192.168.42.82'}
[2021-04-26 16:31:16.794 DEBUG                    django.template : 878]
Exception while resolving variable 'maxLength' in template 'ysdevices/device_form.html'.
Traceback (most recent call last):
  File "/home/nsindiso/.local/lib/python3.6/site-packages/django/template/base.py", line 835, in _resolve_lookup
    current = current[bit]
KeyError: 'maxLength'

During handling of the above exception, another exception occurred:

Traceback (most recent call last):
  File "/home/nsindiso/.local/lib/python3.6/site-packages/django/template/base.py", line 843, in _resolve_lookup
    current = getattr(current, bit)
AttributeError: 'dict' object has no attribute 'maxLength'

During handling of the above exception, another exception occurred:

Traceback (most recent call last):
  File "/home/nsindiso/.local/lib/python3.6/site-packages/django/template/base.py", line 849, in _resolve_lookup
    current = current[int(bit)]
ValueError: invalid literal for int() with base 10: 'maxLength'

During handling of the above exception, another exception occurred:

Traceback (most recent call last):
  File "/home/nsindiso/.local/lib/python3.6/site-packages/django/template/base.py", line 856, in _resolve_lookup
    (bit, current))  # missing attribute
django.template.base.VariableDoesNotExist: Failed lookup for key [maxLength] in {'type': 'string', 'description': 'Address or hostname to use as default for all protocols', 'required': True, 'default': '192.168.42.82'}
[2021-04-26 16:31:16.794 DEBUG                    django.template : 878]
Exception while resolving variable 'step' in template 'ysdevices/device_form.html'.
Traceback (most recent call last):
  File "/home/nsindiso/.local/lib/python3.6/site-packages/django/template/base.py", line 835, in _resolve_lookup
    current = current[bit]
KeyError: 'step'

During handling of the above exception, another exception occurred:

Traceback (most recent call last):
  File "/home/nsindiso/.local/lib/python3.6/site-packages/django/template/base.py", line 843, in _resolve_lookup
    current = getattr(current, bit)
AttributeError: 'dict' object has no attribute 'step'

During handling of the above exception, another exception occurred:

Traceback (most recent call last):
  File "/home/nsindiso/.local/lib/python3.6/site-packages/django/template/base.py", line 849, in _resolve_lookup
    current = current[int(bit)]
ValueError: invalid literal for int() with base 10: 'step'

During handling of the above exception, another exception occurred:

Traceback (most recent call last):
  File "/home/nsindiso/.local/lib/python3.6/site-packages/django/template/base.py", line 856, in _resolve_lookup
    (bit, current))  # missing attribute
django.template.base.VariableDoesNotExist: Failed lookup for key [step] in {'type': 'string', 'description': 'Address or hostname to use as default for all protocols', 'required': True, 'default': '192.168.42.82'}
[2021-04-26 16:31:16.795 DEBUG                    django.template : 878]
Exception while resolving variable 'label' in template 'ysdevices/device_form.html'.
Traceback (most recent call last):
  File "/home/nsindiso/.local/lib/python3.6/site-packages/django/template/base.py", line 835, in _resolve_lookup
    current = current[bit]
KeyError: 'label'

During handling of the above exception, another exception occurred:

Traceback (most recent call last):
  File "/home/nsindiso/.local/lib/python3.6/site-packages/django/template/base.py", line 843, in _resolve_lookup
    current = getattr(current, bit)
AttributeError: 'dict' object has no attribute 'label'

During handling of the above exception, another exception occurred:

Traceback (most recent call last):
  File "/home/nsindiso/.local/lib/python3.6/site-packages/django/template/base.py", line 849, in _resolve_lookup
    current = current[int(bit)]
ValueError: invalid literal for int() with base 10: 'label'

During handling of the above exception, another exception occurred:

Traceback (most recent call last):
  File "/home/nsindiso/.local/lib/python3.6/site-packages/django/template/base.py", line 856, in _resolve_lookup
    (bit, current))  # missing attribute
django.template.base.VariableDoesNotExist: Failed lookup for key [label] in {'type': 'string', 'description': 'Address or hostname to use as default for all protocols', 'required': True, 'default': '192.168.42.82'}
[2021-04-26 16:31:16.797 DEBUG                    django.template : 878]
Exception while resolving variable 'min' in template 'ysdevices/device_form.html'.
Traceback (most recent call last):
  File "/home/nsindiso/.local/lib/python3.6/site-packages/django/template/base.py", line 835, in _resolve_lookup
    current = current[bit]
KeyError: 'min'

During handling of the above exception, another exception occurred:

Traceback (most recent call last):
  File "/home/nsindiso/.local/lib/python3.6/site-packages/django/template/base.py", line 843, in _resolve_lookup
    current = getattr(current, bit)
AttributeError: 'dict' object has no attribute 'min'

During handling of the above exception, another exception occurred:

Traceback (most recent call last):
  File "/home/nsindiso/.local/lib/python3.6/site-packages/django/template/base.py", line 849, in _resolve_lookup
    current = current[int(bit)]
ValueError: invalid literal for int() with base 10: 'min'

During handling of the above exception, another exception occurred:

Traceback (most recent call last):
  File "/home/nsindiso/.local/lib/python3.6/site-packages/django/template/base.py", line 856, in _resolve_lookup
    (bit, current))  # missing attribute
django.template.base.VariableDoesNotExist: Failed lookup for key [min] in {'type': 'string', 'description': 'Username used as default for all protocols', 'maxLength': 50, 'default': 'Nsindiso'}
[2021-04-26 16:31:16.798 DEBUG                    django.template : 878]
Exception while resolving variable 'minLength' in template 'ysdevices/device_form.html'.
Traceback (most recent call last):
  File "/home/nsindiso/.local/lib/python3.6/site-packages/django/template/base.py", line 835, in _resolve_lookup
    current = current[bit]
KeyError: 'minLength'

During handling of the above exception, another exception occurred:

Traceback (most recent call last):
  File "/home/nsindiso/.local/lib/python3.6/site-packages/django/template/base.py", line 843, in _resolve_lookup
    current = getattr(current, bit)
AttributeError: 'dict' object has no attribute 'minLength'

During handling of the above exception, another exception occurred:

Traceback (most recent call last):
  File "/home/nsindiso/.local/lib/python3.6/site-packages/django/template/base.py", line 849, in _resolve_lookup
    current = current[int(bit)]
ValueError: invalid literal for int() with base 10: 'minLength'

During handling of the above exception, another exception occurred:

Traceback (most recent call last):
  File "/home/nsindiso/.local/lib/python3.6/site-packages/django/template/base.py", line 856, in _resolve_lookup
    (bit, current))  # missing attribute
django.template.base.VariableDoesNotExist: Failed lookup for key [minLength] in {'type': 'string', 'description': 'Username used as default for all protocols', 'maxLength': 50, 'default': 'Nsindiso'}
[2021-04-26 16:31:16.799 DEBUG                    django.template : 878]
Exception while resolving variable 'max' in template 'ysdevices/device_form.html'.
Traceback (most recent call last):
  File "/home/nsindiso/.local/lib/python3.6/site-packages/django/template/base.py", line 835, in _resolve_lookup
    current = current[bit]
KeyError: 'max'

During handling of the above exception, another exception occurred:

Traceback (most recent call last):
  File "/home/nsindiso/.local/lib/python3.6/site-packages/django/template/base.py", line 843, in _resolve_lookup
    current = getattr(current, bit)
AttributeError: 'dict' object has no attribute 'max'

During handling of the above exception, another exception occurred:

Traceback (most recent call last):
  File "/home/nsindiso/.local/lib/python3.6/site-packages/django/template/base.py", line 849, in _resolve_lookup
    current = current[int(bit)]
ValueError: invalid literal for int() with base 10: 'max'

During handling of the above exception, another exception occurred:

Traceback (most recent call last):
  File "/home/nsindiso/.local/lib/python3.6/site-packages/django/template/base.py", line 856, in _resolve_lookup
    (bit, current))  # missing attribute
django.template.base.VariableDoesNotExist: Failed lookup for key [max] in {'type': 'string', 'description': 'Username used as default for all protocols', 'maxLength': 50, 'default': 'Nsindiso'}
[2021-04-26 16:31:16.800 DEBUG                    django.template : 878]
Exception while resolving variable 'step' in template 'ysdevices/device_form.html'.
Traceback (most recent call last):
  File "/home/nsindiso/.local/lib/python3.6/site-packages/django/template/base.py", line 835, in _resolve_lookup
    current = current[bit]
KeyError: 'step'

During handling of the above exception, another exception occurred:

Traceback (most recent call last):
  File "/home/nsindiso/.local/lib/python3.6/site-packages/django/template/base.py", line 843, in _resolve_lookup
    current = getattr(current, bit)
AttributeError: 'dict' object has no attribute 'step'

During handling of the above exception, another exception occurred:

Traceback (most recent call last):
  File "/home/nsindiso/.local/lib/python3.6/site-packages/django/template/base.py", line 849, in _resolve_lookup
    current = current[int(bit)]
ValueError: invalid literal for int() with base 10: 'step'

During handling of the above exception, another exception occurred:

Traceback (most recent call last):
  File "/home/nsindiso/.local/lib/python3.6/site-packages/django/template/base.py", line 856, in _resolve_lookup
    (bit, current))  # missing attribute
django.template.base.VariableDoesNotExist: Failed lookup for key [step] in {'type': 'string', 'description': 'Username used as default for all protocols', 'maxLength': 50, 'default': 'Nsindiso'}
[2021-04-26 16:31:16.802 DEBUG                    django.template : 878]
Exception while resolving variable 'required' in template 'ysdevices/device_form.html'.
Traceback (most recent call last):
  File "/home/nsindiso/.local/lib/python3.6/site-packages/django/template/base.py", line 835, in _resolve_lookup
    current = current[bit]
KeyError: 'required'

During handling of the above exception, another exception occurred:

Traceback (most recent call last):
  File "/home/nsindiso/.local/lib/python3.6/site-packages/django/template/base.py", line 843, in _resolve_lookup
    current = getattr(current, bit)
AttributeError: 'dict' object has no attribute 'required'

During handling of the above exception, another exception occurred:

Traceback (most recent call last):
  File "/home/nsindiso/.local/lib/python3.6/site-packages/django/template/base.py", line 849, in _resolve_lookup
    current = current[int(bit)]
ValueError: invalid literal for int() with base 10: 'required'

During handling of the above exception, another exception occurred:

Traceback (most recent call last):
  File "/home/nsindiso/.local/lib/python3.6/site-packages/django/template/base.py", line 856, in _resolve_lookup
    (bit, current))  # missing attribute
django.template.base.VariableDoesNotExist: Failed lookup for key [required] in {'type': 'string', 'description': 'Username used as default for all protocols', 'maxLength': 50, 'default': 'Nsindiso'}
[2021-04-26 16:31:16.803 DEBUG                    django.template : 878]
Exception while resolving variable 'label' in template 'ysdevices/device_form.html'.
Traceback (most recent call last):
  File "/home/nsindiso/.local/lib/python3.6/site-packages/django/template/base.py", line 835, in _resolve_lookup
    current = current[bit]
KeyError: 'label'

During handling of the above exception, another exception occurred:

Traceback (most recent call last):
  File "/home/nsindiso/.local/lib/python3.6/site-packages/django/template/base.py", line 843, in _resolve_lookup
    current = getattr(current, bit)
AttributeError: 'dict' object has no attribute 'label'

During handling of the above exception, another exception occurred:

Traceback (most recent call last):
  File "/home/nsindiso/.local/lib/python3.6/site-packages/django/template/base.py", line 849, in _resolve_lookup
    current = current[int(bit)]
ValueError: invalid literal for int() with base 10: 'label'

During handling of the above exception, another exception occurred:

Traceback (most recent call last):
  File "/home/nsindiso/.local/lib/python3.6/site-packages/django/template/base.py", line 856, in _resolve_lookup
    (bit, current))  # missing attribute
django.template.base.VariableDoesNotExist: Failed lookup for key [label] in {'type': 'string', 'description': 'Username used as default for all protocols', 'maxLength': 50, 'default': 'Nsindiso'}
[2021-04-26 16:31:16.804 DEBUG                    django.template : 878]
Exception while resolving variable 'required' in template 'ysdevices/device_form.html'.
Traceback (most recent call last):
  File "/home/nsindiso/.local/lib/python3.6/site-packages/django/template/base.py", line 835, in _resolve_lookup
    current = current[bit]
KeyError: 'required'

During handling of the above exception, another exception occurred:

Traceback (most recent call last):
  File "/home/nsindiso/.local/lib/python3.6/site-packages/django/template/base.py", line 843, in _resolve_lookup
    current = getattr(current, bit)
AttributeError: 'dict' object has no attribute 'required'

During handling of the above exception, another exception occurred:

Traceback (most recent call last):
  File "/home/nsindiso/.local/lib/python3.6/site-packages/django/template/base.py", line 849, in _resolve_lookup
    current = current[int(bit)]
ValueError: invalid literal for int() with base 10: 'required'

During handling of the above exception, another exception occurred:

Traceback (most recent call last):
  File "/home/nsindiso/.local/lib/python3.6/site-packages/django/template/base.py", line 856, in _resolve_lookup
    (bit, current))  # missing attribute
django.template.base.VariableDoesNotExist: Failed lookup for key [required] in {'type': 'string', 'description': 'Username used as default for all protocols', 'maxLength': 50, 'default': 'Nsindiso'}
[2021-04-26 16:31:16.805 DEBUG                    django.template : 878]
Exception while resolving variable 'min' in template 'ysdevices/device_form.html'.
Traceback (most recent call last):
  File "/home/nsindiso/.local/lib/python3.6/site-packages/django/template/base.py", line 835, in _resolve_lookup
    current = current[bit]
KeyError: 'min'

During handling of the above exception, another exception occurred:

Traceback (most recent call last):
  File "/home/nsindiso/.local/lib/python3.6/site-packages/django/template/base.py", line 843, in _resolve_lookup
    current = getattr(current, bit)
AttributeError: 'dict' object has no attribute 'min'

During handling of the above exception, another exception occurred:

Traceback (most recent call last):
  File "/home/nsindiso/.local/lib/python3.6/site-packages/django/template/base.py", line 849, in _resolve_lookup
    current = current[int(bit)]
ValueError: invalid literal for int() with base 10: 'min'

During handling of the above exception, another exception occurred:

Traceback (most recent call last):
  File "/home/nsindiso/.local/lib/python3.6/site-packages/django/template/base.py", line 856, in _resolve_lookup
    (bit, current))  # missing attribute
django.template.base.VariableDoesNotExist: Failed lookup for key [min] in {'type': 'password', 'description': 'Password used as default for all protocols', 'maxLength': 50, 'default': '_placeholder_'}
[2021-04-26 16:31:16.806 DEBUG                    django.template : 878]
Exception while resolving variable 'minLength' in template 'ysdevices/device_form.html'.
Traceback (most recent call last):
  File "/home/nsindiso/.local/lib/python3.6/site-packages/django/template/base.py", line 835, in _resolve_lookup
    current = current[bit]
KeyError: 'minLength'

During handling of the above exception, another exception occurred:

Traceback (most recent call last):
  File "/home/nsindiso/.local/lib/python3.6/site-packages/django/template/base.py", line 843, in _resolve_lookup
    current = getattr(current, bit)
AttributeError: 'dict' object has no attribute 'minLength'

During handling of the above exception, another exception occurred:

Traceback (most recent call last):
  File "/home/nsindiso/.local/lib/python3.6/site-packages/django/template/base.py", line 849, in _resolve_lookup
    current = current[int(bit)]
ValueError: invalid literal for int() with base 10: 'minLength'

During handling of the above exception, another exception occurred:

Traceback (most recent call last):
  File "/home/nsindiso/.local/lib/python3.6/site-packages/django/template/base.py", line 856, in _resolve_lookup
    (bit, current))  # missing attribute
django.template.base.VariableDoesNotExist: Failed lookup for key [minLength] in {'type': 'password', 'description': 'Password used as default for all protocols', 'maxLength': 50, 'default': '_placeholder_'}
[2021-04-26 16:31:16.808 DEBUG                    django.template : 878]
Exception while resolving variable 'max' in template 'ysdevices/device_form.html'.
Traceback (most recent call last):
  File "/home/nsindiso/.local/lib/python3.6/site-packages/django/template/base.py", line 835, in _resolve_lookup
    current = current[bit]
KeyError: 'max'

During handling of the above exception, another exception occurred:

Traceback (most recent call last):
  File "/home/nsindiso/.local/lib/python3.6/site-packages/django/template/base.py", line 843, in _resolve_lookup
    current = getattr(current, bit)
AttributeError: 'dict' object has no attribute 'max'

During handling of the above exception, another exception occurred:

Traceback (most recent call last):
  File "/home/nsindiso/.local/lib/python3.6/site-packages/django/template/base.py", line 849, in _resolve_lookup
    current = current[int(bit)]
ValueError: invalid literal for int() with base 10: 'max'

During handling of the above exception, another exception occurred:

Traceback (most recent call last):
  File "/home/nsindiso/.local/lib/python3.6/site-packages/django/template/base.py", line 856, in _resolve_lookup
    (bit, current))  # missing attribute
django.template.base.VariableDoesNotExist: Failed lookup for key [max] in {'type': 'password', 'description': 'Password used as default for all protocols', 'maxLength': 50, 'default': '_placeholder_'}
[2021-04-26 16:31:16.809 DEBUG                    django.template : 878]
Exception while resolving variable 'step' in template 'ysdevices/device_form.html'.
Traceback (most recent call last):
  File "/home/nsindiso/.local/lib/python3.6/site-packages/django/template/base.py", line 835, in _resolve_lookup
    current = current[bit]
KeyError: 'step'

During handling of the above exception, another exception occurred:

Traceback (most recent call last):
  File "/home/nsindiso/.local/lib/python3.6/site-packages/django/template/base.py", line 843, in _resolve_lookup
    current = getattr(current, bit)
AttributeError: 'dict' object has no attribute 'step'

During handling of the above exception, another exception occurred:

Traceback (most recent call last):
  File "/home/nsindiso/.local/lib/python3.6/site-packages/django/template/base.py", line 849, in _resolve_lookup
    current = current[int(bit)]
ValueError: invalid literal for int() with base 10: 'step'

During handling of the above exception, another exception occurred:

Traceback (most recent call last):
  File "/home/nsindiso/.local/lib/python3.6/site-packages/django/template/base.py", line 856, in _resolve_lookup
    (bit, current))  # missing attribute
django.template.base.VariableDoesNotExist: Failed lookup for key [step] in {'type': 'password', 'description': 'Password used as default for all protocols', 'maxLength': 50, 'default': '_placeholder_'}
[2021-04-26 16:31:16.810 DEBUG                    django.template : 878]
Exception while resolving variable 'required' in template 'ysdevices/device_form.html'.
Traceback (most recent call last):
  File "/home/nsindiso/.local/lib/python3.6/site-packages/django/template/base.py", line 835, in _resolve_lookup
    current = current[bit]
KeyError: 'required'

During handling of the above exception, another exception occurred:

Traceback (most recent call last):
  File "/home/nsindiso/.local/lib/python3.6/site-packages/django/template/base.py", line 843, in _resolve_lookup
    current = getattr(current, bit)
AttributeError: 'dict' object has no attribute 'required'

During handling of the above exception, another exception occurred:

Traceback (most recent call last):
  File "/home/nsindiso/.local/lib/python3.6/site-packages/django/template/base.py", line 849, in _resolve_lookup
    current = current[int(bit)]
ValueError: invalid literal for int() with base 10: 'required'

During handling of the above exception, another exception occurred:

Traceback (most recent call last):
  File "/home/nsindiso/.local/lib/python3.6/site-packages/django/template/base.py", line 856, in _resolve_lookup
    (bit, current))  # missing attribute
django.template.base.VariableDoesNotExist: Failed lookup for key [required] in {'type': 'password', 'description': 'Password used as default for all protocols', 'maxLength': 50, 'default': '_placeholder_'}
[2021-04-26 16:31:16.812 DEBUG                    django.template : 878]
Exception while resolving variable 'label' in template 'ysdevices/device_form.html'.
Traceback (most recent call last):
  File "/home/nsindiso/.local/lib/python3.6/site-packages/django/template/base.py", line 835, in _resolve_lookup
    current = current[bit]
KeyError: 'label'

During handling of the above exception, another exception occurred:

Traceback (most recent call last):
  File "/home/nsindiso/.local/lib/python3.6/site-packages/django/template/base.py", line 843, in _resolve_lookup
    current = getattr(current, bit)
AttributeError: 'dict' object has no attribute 'label'

During handling of the above exception, another exception occurred:

Traceback (most recent call last):
  File "/home/nsindiso/.local/lib/python3.6/site-packages/django/template/base.py", line 849, in _resolve_lookup
    current = current[int(bit)]
ValueError: invalid literal for int() with base 10: 'label'

During handling of the above exception, another exception occurred:

Traceback (most recent call last):
  File "/home/nsindiso/.local/lib/python3.6/site-packages/django/template/base.py", line 856, in _resolve_lookup
    (bit, current))  # missing attribute
django.template.base.VariableDoesNotExist: Failed lookup for key [label] in {'type': 'password', 'description': 'Password used as default for all protocols', 'maxLength': 50, 'default': '_placeholder_'}
[2021-04-26 16:31:16.812 DEBUG                    django.template : 878]
Exception while resolving variable 'required' in template 'ysdevices/device_form.html'.
Traceback (most recent call last):
  File "/home/nsindiso/.local/lib/python3.6/site-packages/django/template/base.py", line 835, in _resolve_lookup
    current = current[bit]
KeyError: 'required'

During handling of the above exception, another exception occurred:

Traceback (most recent call last):
  File "/home/nsindiso/.local/lib/python3.6/site-packages/django/template/base.py", line 843, in _resolve_lookup
    current = getattr(current, bit)
AttributeError: 'dict' object has no attribute 'required'

During handling of the above exception, another exception occurred:

Traceback (most recent call last):
  File "/home/nsindiso/.local/lib/python3.6/site-packages/django/template/base.py", line 849, in _resolve_lookup
    current = current[int(bit)]
ValueError: invalid literal for int() with base 10: 'required'

During handling of the above exception, another exception occurred:

Traceback (most recent call last):
  File "/home/nsindiso/.local/lib/python3.6/site-packages/django/template/base.py", line 856, in _resolve_lookup
    (bit, current))  # missing attribute
django.template.base.VariableDoesNotExist: Failed lookup for key [required] in {'type': 'password', 'description': 'Password used as default for all protocols', 'maxLength': 50, 'default': '_placeholder_'}
[2021-04-26 16:31:16.814 DEBUG                    django.template : 878]
Exception while resolving variable 'min' in template 'ysdevices/device_form.html'.
Traceback (most recent call last):
  File "/home/nsindiso/.local/lib/python3.6/site-packages/django/template/base.py", line 835, in _resolve_lookup
    current = current[bit]
KeyError: 'min'

During handling of the above exception, another exception occurred:

Traceback (most recent call last):
  File "/home/nsindiso/.local/lib/python3.6/site-packages/django/template/base.py", line 843, in _resolve_lookup
    current = getattr(current, bit)
AttributeError: 'dict' object has no attribute 'min'

During handling of the above exception, another exception occurred:

Traceback (most recent call last):
  File "/home/nsindiso/.local/lib/python3.6/site-packages/django/template/base.py", line 849, in _resolve_lookup
    current = current[int(bit)]
ValueError: invalid literal for int() with base 10: 'min'

During handling of the above exception, another exception occurred:

Traceback (most recent call last):
  File "/home/nsindiso/.local/lib/python3.6/site-packages/django/template/base.py", line 856, in _resolve_lookup
    (bit, current))  # missing attribute
django.template.base.VariableDoesNotExist: Failed lookup for key [min] in {'type': 'int', 'description': 'Timeout (in seconds) as default for all protocols', 'default': 30, 'required': True}
[2021-04-26 16:31:16.815 DEBUG                    django.template : 878]
Exception while resolving variable 'minLength' in template 'ysdevices/device_form.html'.
Traceback (most recent call last):
  File "/home/nsindiso/.local/lib/python3.6/site-packages/django/template/base.py", line 835, in _resolve_lookup
    current = current[bit]
KeyError: 'minLength'

During handling of the above exception, another exception occurred:

Traceback (most recent call last):
  File "/home/nsindiso/.local/lib/python3.6/site-packages/django/template/base.py", line 843, in _resolve_lookup
    current = getattr(current, bit)
AttributeError: 'dict' object has no attribute 'minLength'

During handling of the above exception, another exception occurred:

Traceback (most recent call last):
  File "/home/nsindiso/.local/lib/python3.6/site-packages/django/template/base.py", line 849, in _resolve_lookup
    current = current[int(bit)]
ValueError: invalid literal for int() with base 10: 'minLength'

During handling of the above exception, another exception occurred:

Traceback (most recent call last):
  File "/home/nsindiso/.local/lib/python3.6/site-packages/django/template/base.py", line 856, in _resolve_lookup
    (bit, current))  # missing attribute
django.template.base.VariableDoesNotExist: Failed lookup for key [minLength] in {'type': 'int', 'description': 'Timeout (in seconds) as default for all protocols', 'default': 30, 'required': True}
[2021-04-26 16:31:16.816 DEBUG                    django.template : 878]
Exception while resolving variable 'max' in template 'ysdevices/device_form.html'.
Traceback (most recent call last):
  File "/home/nsindiso/.local/lib/python3.6/site-packages/django/template/base.py", line 835, in _resolve_lookup
    current = current[bit]
KeyError: 'max'

During handling of the above exception, another exception occurred:

Traceback (most recent call last):
  File "/home/nsindiso/.local/lib/python3.6/site-packages/django/template/base.py", line 843, in _resolve_lookup
    current = getattr(current, bit)
AttributeError: 'dict' object has no attribute 'max'

During handling of the above exception, another exception occurred:

Traceback (most recent call last):
  File "/home/nsindiso/.local/lib/python3.6/site-packages/django/template/base.py", line 849, in _resolve_lookup
    current = current[int(bit)]
ValueError: invalid literal for int() with base 10: 'max'

During handling of the above exception, another exception occurred:

Traceback (most recent call last):
  File "/home/nsindiso/.local/lib/python3.6/site-packages/django/template/base.py", line 856, in _resolve_lookup
    (bit, current))  # missing attribute
django.template.base.VariableDoesNotExist: Failed lookup for key [max] in {'type': 'int', 'description': 'Timeout (in seconds) as default for all protocols', 'default': 30, 'required': True}
[2021-04-26 16:31:16.817 DEBUG                    django.template : 878]
Exception while resolving variable 'maxLength' in template 'ysdevices/device_form.html'.
Traceback (most recent call last):
  File "/home/nsindiso/.local/lib/python3.6/site-packages/django/template/base.py", line 835, in _resolve_lookup
    current = current[bit]
KeyError: 'maxLength'

During handling of the above exception, another exception occurred:

Traceback (most recent call last):
  File "/home/nsindiso/.local/lib/python3.6/site-packages/django/template/base.py", line 843, in _resolve_lookup
    current = getattr(current, bit)
AttributeError: 'dict' object has no attribute 'maxLength'

During handling of the above exception, another exception occurred:

Traceback (most recent call last):
  File "/home/nsindiso/.local/lib/python3.6/site-packages/django/template/base.py", line 849, in _resolve_lookup
    current = current[int(bit)]
ValueError: invalid literal for int() with base 10: 'maxLength'

During handling of the above exception, another exception occurred:

Traceback (most recent call last):
  File "/home/nsindiso/.local/lib/python3.6/site-packages/django/template/base.py", line 856, in _resolve_lookup
    (bit, current))  # missing attribute
django.template.base.VariableDoesNotExist: Failed lookup for key [maxLength] in {'type': 'int', 'description': 'Timeout (in seconds) as default for all protocols', 'default': 30, 'required': True}
[2021-04-26 16:31:16.818 DEBUG                    django.template : 878]
Exception while resolving variable 'step' in template 'ysdevices/device_form.html'.
Traceback (most recent call last):
  File "/home/nsindiso/.local/lib/python3.6/site-packages/django/template/base.py", line 835, in _resolve_lookup
    current = current[bit]
KeyError: 'step'

During handling of the above exception, another exception occurred:

Traceback (most recent call last):
  File "/home/nsindiso/.local/lib/python3.6/site-packages/django/template/base.py", line 843, in _resolve_lookup
    current = getattr(current, bit)
AttributeError: 'dict' object has no attribute 'step'

During handling of the above exception, another exception occurred:

Traceback (most recent call last):
  File "/home/nsindiso/.local/lib/python3.6/site-packages/django/template/base.py", line 849, in _resolve_lookup
    current = current[int(bit)]
ValueError: invalid literal for int() with base 10: 'step'

During handling of the above exception, another exception occurred:

Traceback (most recent call last):
  File "/home/nsindiso/.local/lib/python3.6/site-packages/django/template/base.py", line 856, in _resolve_lookup
    (bit, current))  # missing attribute
django.template.base.VariableDoesNotExist: Failed lookup for key [step] in {'type': 'int', 'description': 'Timeout (in seconds) as default for all protocols', 'default': 30, 'required': True}
[2021-04-26 16:31:16.820 DEBUG                    django.template : 878]
Exception while resolving variable 'label' in template 'ysdevices/device_form.html'.
Traceback (most recent call last):
  File "/home/nsindiso/.local/lib/python3.6/site-packages/django/template/base.py", line 835, in _resolve_lookup
    current = current[bit]
KeyError: 'label'

During handling of the above exception, another exception occurred:

Traceback (most recent call last):
  File "/home/nsindiso/.local/lib/python3.6/site-packages/django/template/base.py", line 843, in _resolve_lookup
    current = getattr(current, bit)
AttributeError: 'dict' object has no attribute 'label'

During handling of the above exception, another exception occurred:

Traceback (most recent call last):
  File "/home/nsindiso/.local/lib/python3.6/site-packages/django/template/base.py", line 849, in _resolve_lookup
    current = current[int(bit)]
ValueError: invalid literal for int() with base 10: 'label'

During handling of the above exception, another exception occurred:

Traceback (most recent call last):
  File "/home/nsindiso/.local/lib/python3.6/site-packages/django/template/base.py", line 856, in _resolve_lookup
    (bit, current))  # missing attribute
django.template.base.VariableDoesNotExist: Failed lookup for key [label] in {'type': 'int', 'description': 'Timeout (in seconds) as default for all protocols', 'default': 30, 'required': True}
[2021-04-26 16:31:16.823 DEBUG                    django.template : 878]
Exception while resolving variable 'label' in template 'ysdevices/device_form.html'.
Traceback (most recent call last):
  File "/home/nsindiso/.local/lib/python3.6/site-packages/django/template/base.py", line 835, in _resolve_lookup
    current = current[bit]
KeyError: 'label'

During handling of the above exception, another exception occurred:

Traceback (most recent call last):
  File "/home/nsindiso/.local/lib/python3.6/site-packages/django/template/base.py", line 843, in _resolve_lookup
    current = getattr(current, bit)
AttributeError: 'dict' object has no attribute 'label'

During handling of the above exception, another exception occurred:

Traceback (most recent call last):
  File "/home/nsindiso/.local/lib/python3.6/site-packages/django/template/base.py", line 849, in _resolve_lookup
    current = current[int(bit)]
ValueError: invalid literal for int() with base 10: 'label'

During handling of the above exception, another exception occurred:

Traceback (most recent call last):
  File "/home/nsindiso/.local/lib/python3.6/site-packages/django/template/base.py", line 856, in _resolve_lookup
    (bit, current))  # missing attribute
django.template.base.VariableDoesNotExist: Failed lookup for key [label] in {'type': 'dict', 'description': 'Key/value pairs of data associated with device', 'keyLabel': 'Variable Name', 'valueLabel': 'Value', 'default': {}}
[2021-04-26 16:31:16.823 DEBUG                    django.template : 878]
Exception while resolving variable 'required' in template 'ysdevices/device_form.html'.
Traceback (most recent call last):
  File "/home/nsindiso/.local/lib/python3.6/site-packages/django/template/base.py", line 835, in _resolve_lookup
    current = current[bit]
KeyError: 'required'

During handling of the above exception, another exception occurred:

Traceback (most recent call last):
  File "/home/nsindiso/.local/lib/python3.6/site-packages/django/template/base.py", line 843, in _resolve_lookup
    current = getattr(current, bit)
AttributeError: 'dict' object has no attribute 'required'

During handling of the above exception, another exception occurred:

Traceback (most recent call last):
  File "/home/nsindiso/.local/lib/python3.6/site-packages/django/template/base.py", line 849, in _resolve_lookup
    current = current[int(bit)]
ValueError: invalid literal for int() with base 10: 'required'

During handling of the above exception, another exception occurred:

Traceback (most recent call last):
  File "/home/nsindiso/.local/lib/python3.6/site-packages/django/template/base.py", line 856, in _resolve_lookup
    (bit, current))  # missing attribute
django.template.base.VariableDoesNotExist: Failed lookup for key [required] in {'type': 'dict', 'description': 'Key/value pairs of data associated with device', 'keyLabel': 'Variable Name', 'valueLabel': 'Value', 'default': {}}
[2021-04-26 16:31:16.826 DEBUG                    django.template : 878]
Exception while resolving variable 'description' in template 'ysdevices/device_form.html'.
Traceback (most recent call last):
  File "/home/nsindiso/.local/lib/python3.6/site-packages/django/template/base.py", line 835, in _resolve_lookup
    current = current[bit]
KeyError: 'description'

During handling of the above exception, another exception occurred:

Traceback (most recent call last):
  File "/home/nsindiso/.local/lib/python3.6/site-packages/django/template/base.py", line 843, in _resolve_lookup
    current = getattr(current, bit)
AttributeError: 'dict' object has no attribute 'description'

During handling of the above exception, another exception occurred:

Traceback (most recent call last):
  File "/home/nsindiso/.local/lib/python3.6/site-packages/django/template/base.py", line 849, in _resolve_lookup
    current = current[int(bit)]
ValueError: invalid literal for int() with base 10: 'description'

During handling of the above exception, another exception occurred:

Traceback (most recent call last):
  File "/home/nsindiso/.local/lib/python3.6/site-packages/django/template/base.py", line 856, in _resolve_lookup
    (bit, current))  # missing attribute
django.template.base.VariableDoesNotExist: Failed lookup for key [description] in {'label': 'Device supports NETCONF', 'type': 'boolean', 'default': True}
[2021-04-26 16:31:16.829 DEBUG                    django.template : 878]
Exception while resolving variable 'minLength' in template 'ysdevices/device_form.html'.
Traceback (most recent call last):
  File "/home/nsindiso/.local/lib/python3.6/site-packages/django/template/base.py", line 835, in _resolve_lookup
    current = current[bit]
KeyError: 'minLength'

During handling of the above exception, another exception occurred:

Traceback (most recent call last):
  File "/home/nsindiso/.local/lib/python3.6/site-packages/django/template/base.py", line 843, in _resolve_lookup
    current = getattr(current, bit)
AttributeError: 'dict' object has no attribute 'minLength'

During handling of the above exception, another exception occurred:

Traceback (most recent call last):
  File "/home/nsindiso/.local/lib/python3.6/site-packages/django/template/base.py", line 849, in _resolve_lookup
    current = current[int(bit)]
ValueError: invalid literal for int() with base 10: 'minLength'

During handling of the above exception, another exception occurred:

Traceback (most recent call last):
  File "/home/nsindiso/.local/lib/python3.6/site-packages/django/template/base.py", line 856, in _resolve_lookup
    (bit, current))  # missing attribute
django.template.base.VariableDoesNotExist: Failed lookup for key [minLength] in {'label': 'NETCONF port', 'type': 'int', 'description': 'Port number NETCONF listens on', 'min': 1, 'max': 65535, 'default': 830, 'required': True}
[2021-04-26 16:31:16.830 DEBUG                    django.template : 878]
Exception while resolving variable 'maxLength' in template 'ysdevices/device_form.html'.
Traceback (most recent call last):
  File "/home/nsindiso/.local/lib/python3.6/site-packages/django/template/base.py", line 835, in _resolve_lookup
    current = current[bit]
KeyError: 'maxLength'

During handling of the above exception, another exception occurred:

Traceback (most recent call last):
  File "/home/nsindiso/.local/lib/python3.6/site-packages/django/template/base.py", line 843, in _resolve_lookup
    current = getattr(current, bit)
AttributeError: 'dict' object has no attribute 'maxLength'

During handling of the above exception, another exception occurred:

Traceback (most recent call last):
  File "/home/nsindiso/.local/lib/python3.6/site-packages/django/template/base.py", line 849, in _resolve_lookup
    current = current[int(bit)]
ValueError: invalid literal for int() with base 10: 'maxLength'

During handling of the above exception, another exception occurred:

Traceback (most recent call last):
  File "/home/nsindiso/.local/lib/python3.6/site-packages/django/template/base.py", line 856, in _resolve_lookup
    (bit, current))  # missing attribute
django.template.base.VariableDoesNotExist: Failed lookup for key [maxLength] in {'label': 'NETCONF port', 'type': 'int', 'description': 'Port number NETCONF listens on', 'min': 1, 'max': 65535, 'default': 830, 'required': True}
[2021-04-26 16:31:16.831 DEBUG                    django.template : 878]
Exception while resolving variable 'step' in template 'ysdevices/device_form.html'.
Traceback (most recent call last):
  File "/home/nsindiso/.local/lib/python3.6/site-packages/django/template/base.py", line 835, in _resolve_lookup
    current = current[bit]
KeyError: 'step'

During handling of the above exception, another exception occurred:

Traceback (most recent call last):
  File "/home/nsindiso/.local/lib/python3.6/site-packages/django/template/base.py", line 843, in _resolve_lookup
    current = getattr(current, bit)
AttributeError: 'dict' object has no attribute 'step'

During handling of the above exception, another exception occurred:

Traceback (most recent call last):
  File "/home/nsindiso/.local/lib/python3.6/site-packages/django/template/base.py", line 849, in _resolve_lookup
    current = current[int(bit)]
ValueError: invalid literal for int() with base 10: 'step'

During handling of the above exception, another exception occurred:

Traceback (most recent call last):
  File "/home/nsindiso/.local/lib/python3.6/site-packages/django/template/base.py", line 856, in _resolve_lookup
    (bit, current))  # missing attribute
django.template.base.VariableDoesNotExist: Failed lookup for key [step] in {'label': 'NETCONF port', 'type': 'int', 'description': 'Port number NETCONF listens on', 'min': 1, 'max': 65535, 'default': 830, 'required': True}
[2021-04-26 16:31:16.832 DEBUG                    django.template : 878]
Exception while resolving variable 'description' in template 'ysdevices/device_form.html'.
Traceback (most recent call last):
  File "/home/nsindiso/.local/lib/python3.6/site-packages/django/template/base.py", line 835, in _resolve_lookup
    current = current[bit]
KeyError: 'description'

During handling of the above exception, another exception occurred:

Traceback (most recent call last):
  File "/home/nsindiso/.local/lib/python3.6/site-packages/django/template/base.py", line 843, in _resolve_lookup
    current = getattr(current, bit)
AttributeError: 'dict' object has no attribute 'description'

During handling of the above exception, another exception occurred:

Traceback (most recent call last):
  File "/home/nsindiso/.local/lib/python3.6/site-packages/django/template/base.py", line 849, in _resolve_lookup
    current = current[int(bit)]
ValueError: invalid literal for int() with base 10: 'description'

During handling of the above exception, another exception occurred:

Traceback (most recent call last):
  File "/home/nsindiso/.local/lib/python3.6/site-packages/django/template/base.py", line 856, in _resolve_lookup
    (bit, current))  # missing attribute
django.template.base.VariableDoesNotExist: Failed lookup for key [description] in {'label': 'Skip SSH key validation for this device', 'type': 'boolean', 'default': True}
[2021-04-26 16:31:16.834 DEBUG                    django.template : 878]
Exception while resolving variable 'min' in template 'ysdevices/device_form.html'.
Traceback (most recent call last):
  File "/home/nsindiso/.local/lib/python3.6/site-packages/django/template/base.py", line 835, in _resolve_lookup
    current = current[bit]
KeyError: 'min'

During handling of the above exception, another exception occurred:

Traceback (most recent call last):
  File "/home/nsindiso/.local/lib/python3.6/site-packages/django/template/base.py", line 843, in _resolve_lookup
    current = getattr(current, bit)
AttributeError: 'dict' object has no attribute 'min'

During handling of the above exception, another exception occurred:

Traceback (most recent call last):
  File "/home/nsindiso/.local/lib/python3.6/site-packages/django/template/base.py", line 849, in _resolve_lookup
    current = current[int(bit)]
ValueError: invalid literal for int() with base 10: 'min'

During handling of the above exception, another exception occurred:

Traceback (most recent call last):
  File "/home/nsindiso/.local/lib/python3.6/site-packages/django/template/base.py", line 856, in _resolve_lookup
    (bit, current))  # missing attribute
django.template.base.VariableDoesNotExist: Failed lookup for key [min] in {'type': 'string', 'description': 'Address or hostname to access via NETCONF', 'default': ''}
[2021-04-26 16:31:16.835 DEBUG                    django.template : 878]
Exception while resolving variable 'minLength' in template 'ysdevices/device_form.html'.
Traceback (most recent call last):
  File "/home/nsindiso/.local/lib/python3.6/site-packages/django/template/base.py", line 835, in _resolve_lookup
    current = current[bit]
KeyError: 'minLength'

During handling of the above exception, another exception occurred:

Traceback (most recent call last):
  File "/home/nsindiso/.local/lib/python3.6/site-packages/django/template/base.py", line 843, in _resolve_lookup
    current = getattr(current, bit)
AttributeError: 'dict' object has no attribute 'minLength'

During handling of the above exception, another exception occurred:

Traceback (most recent call last):
  File "/home/nsindiso/.local/lib/python3.6/site-packages/django/template/base.py", line 849, in _resolve_lookup
    current = current[int(bit)]
ValueError: invalid literal for int() with base 10: 'minLength'

During handling of the above exception, another exception occurred:

Traceback (most recent call last):
  File "/home/nsindiso/.local/lib/python3.6/site-packages/django/template/base.py", line 856, in _resolve_lookup
    (bit, current))  # missing attribute
django.template.base.VariableDoesNotExist: Failed lookup for key [minLength] in {'type': 'string', 'description': 'Address or hostname to access via NETCONF', 'default': ''}
[2021-04-26 16:31:16.835 DEBUG                    django.template : 878]
Exception while resolving variable 'max' in template 'ysdevices/device_form.html'.
Traceback (most recent call last):
  File "/home/nsindiso/.local/lib/python3.6/site-packages/django/template/base.py", line 835, in _resolve_lookup
    current = current[bit]
KeyError: 'max'

During handling of the above exception, another exception occurred:

Traceback (most recent call last):
  File "/home/nsindiso/.local/lib/python3.6/site-packages/django/template/base.py", line 843, in _resolve_lookup
    current = getattr(current, bit)
AttributeError: 'dict' object has no attribute 'max'

During handling of the above exception, another exception occurred:

Traceback (most recent call last):
  File "/home/nsindiso/.local/lib/python3.6/site-packages/django/template/base.py", line 849, in _resolve_lookup
    current = current[int(bit)]
ValueError: invalid literal for int() with base 10: 'max'

During handling of the above exception, another exception occurred:

Traceback (most recent call last):
  File "/home/nsindiso/.local/lib/python3.6/site-packages/django/template/base.py", line 856, in _resolve_lookup
    (bit, current))  # missing attribute
django.template.base.VariableDoesNotExist: Failed lookup for key [max] in {'type': 'string', 'description': 'Address or hostname to access via NETCONF', 'default': ''}
[2021-04-26 16:31:16.836 DEBUG                    django.template : 878]
Exception while resolving variable 'maxLength' in template 'ysdevices/device_form.html'.
Traceback (most recent call last):
  File "/home/nsindiso/.local/lib/python3.6/site-packages/django/template/base.py", line 835, in _resolve_lookup
    current = current[bit]
KeyError: 'maxLength'

During handling of the above exception, another exception occurred:

Traceback (most recent call last):
  File "/home/nsindiso/.local/lib/python3.6/site-packages/django/template/base.py", line 843, in _resolve_lookup
    current = getattr(current, bit)
AttributeError: 'dict' object has no attribute 'maxLength'

During handling of the above exception, another exception occurred:

Traceback (most recent call last):
  File "/home/nsindiso/.local/lib/python3.6/site-packages/django/template/base.py", line 849, in _resolve_lookup
    current = current[int(bit)]
ValueError: invalid literal for int() with base 10: 'maxLength'

During handling of the above exception, another exception occurred:

Traceback (most recent call last):
  File "/home/nsindiso/.local/lib/python3.6/site-packages/django/template/base.py", line 856, in _resolve_lookup
    (bit, current))  # missing attribute
django.template.base.VariableDoesNotExist: Failed lookup for key [maxLength] in {'type': 'string', 'description': 'Address or hostname to access via NETCONF', 'default': ''}
[2021-04-26 16:31:16.837 DEBUG                    django.template : 878]
Exception while resolving variable 'step' in template 'ysdevices/device_form.html'.
Traceback (most recent call last):
  File "/home/nsindiso/.local/lib/python3.6/site-packages/django/template/base.py", line 835, in _resolve_lookup
    current = current[bit]
KeyError: 'step'

During handling of the above exception, another exception occurred:

Traceback (most recent call last):
  File "/home/nsindiso/.local/lib/python3.6/site-packages/django/template/base.py", line 843, in _resolve_lookup
    current = getattr(current, bit)
AttributeError: 'dict' object has no attribute 'step'

During handling of the above exception, another exception occurred:

Traceback (most recent call last):
  File "/home/nsindiso/.local/lib/python3.6/site-packages/django/template/base.py", line 849, in _resolve_lookup
    current = current[int(bit)]
ValueError: invalid literal for int() with base 10: 'step'

During handling of the above exception, another exception occurred:

Traceback (most recent call last):
  File "/home/nsindiso/.local/lib/python3.6/site-packages/django/template/base.py", line 856, in _resolve_lookup
    (bit, current))  # missing attribute
django.template.base.VariableDoesNotExist: Failed lookup for key [step] in {'type': 'string', 'description': 'Address or hostname to access via NETCONF', 'default': ''}
[2021-04-26 16:31:16.838 DEBUG                    django.template : 878]
Exception while resolving variable 'required' in template 'ysdevices/device_form.html'.
Traceback (most recent call last):
  File "/home/nsindiso/.local/lib/python3.6/site-packages/django/template/base.py", line 835, in _resolve_lookup
    current = current[bit]
KeyError: 'required'

During handling of the above exception, another exception occurred:

Traceback (most recent call last):
  File "/home/nsindiso/.local/lib/python3.6/site-packages/django/template/base.py", line 843, in _resolve_lookup
    current = getattr(current, bit)
AttributeError: 'dict' object has no attribute 'required'

During handling of the above exception, another exception occurred:

Traceback (most recent call last):
  File "/home/nsindiso/.local/lib/python3.6/site-packages/django/template/base.py", line 849, in _resolve_lookup
    current = current[int(bit)]
ValueError: invalid literal for int() with base 10: 'required'

During handling of the above exception, another exception occurred:

Traceback (most recent call last):
  File "/home/nsindiso/.local/lib/python3.6/site-packages/django/template/base.py", line 856, in _resolve_lookup
    (bit, current))  # missing attribute
django.template.base.VariableDoesNotExist: Failed lookup for key [required] in {'type': 'string', 'description': 'Address or hostname to access via NETCONF', 'default': ''}
[2021-04-26 16:31:16.839 DEBUG                    django.template : 878]
Exception while resolving variable 'required' in template 'ysdevices/device_form.html'.
Traceback (most recent call last):
  File "/home/nsindiso/.local/lib/python3.6/site-packages/django/template/base.py", line 835, in _resolve_lookup
    current = current[bit]
KeyError: 'required'

During handling of the above exception, another exception occurred:

Traceback (most recent call last):
  File "/home/nsindiso/.local/lib/python3.6/site-packages/django/template/base.py", line 843, in _resolve_lookup
    current = getattr(current, bit)
AttributeError: 'dict' object has no attribute 'required'

During handling of the above exception, another exception occurred:

Traceback (most recent call last):
  File "/home/nsindiso/.local/lib/python3.6/site-packages/django/template/base.py", line 849, in _resolve_lookup
    current = current[int(bit)]
ValueError: invalid literal for int() with base 10: 'required'

During handling of the above exception, another exception occurred:

Traceback (most recent call last):
  File "/home/nsindiso/.local/lib/python3.6/site-packages/django/template/base.py", line 856, in _resolve_lookup
    (bit, current))  # missing attribute
django.template.base.VariableDoesNotExist: Failed lookup for key [required] in {'type': 'string', 'description': 'Address or hostname to access via NETCONF', 'default': ''}
[2021-04-26 16:31:16.840 DEBUG                    django.template : 878]
Exception while resolving variable 'label' in template 'ysdevices/device_form.html'.
Traceback (most recent call last):
  File "/home/nsindiso/.local/lib/python3.6/site-packages/django/template/base.py", line 835, in _resolve_lookup
    current = current[bit]
KeyError: 'label'

During handling of the above exception, another exception occurred:

Traceback (most recent call last):
  File "/home/nsindiso/.local/lib/python3.6/site-packages/django/template/base.py", line 843, in _resolve_lookup
    current = getattr(current, bit)
AttributeError: 'dict' object has no attribute 'label'

During handling of the above exception, another exception occurred:

Traceback (most recent call last):
  File "/home/nsindiso/.local/lib/python3.6/site-packages/django/template/base.py", line 849, in _resolve_lookup
    current = current[int(bit)]
ValueError: invalid literal for int() with base 10: 'label'

During handling of the above exception, another exception occurred:

Traceback (most recent call last):
  File "/home/nsindiso/.local/lib/python3.6/site-packages/django/template/base.py", line 856, in _resolve_lookup
    (bit, current))  # missing attribute
django.template.base.VariableDoesNotExist: Failed lookup for key [label] in {'type': 'string', 'description': 'Address or hostname to access via NETCONF', 'default': ''}
[2021-04-26 16:31:16.841 DEBUG                    django.template : 878]
Exception while resolving variable 'required' in template 'ysdevices/device_form.html'.
Traceback (most recent call last):
  File "/home/nsindiso/.local/lib/python3.6/site-packages/django/template/base.py", line 835, in _resolve_lookup
    current = current[bit]
KeyError: 'required'

During handling of the above exception, another exception occurred:

Traceback (most recent call last):
  File "/home/nsindiso/.local/lib/python3.6/site-packages/django/template/base.py", line 843, in _resolve_lookup
    current = getattr(current, bit)
AttributeError: 'dict' object has no attribute 'required'

During handling of the above exception, another exception occurred:

Traceback (most recent call last):
  File "/home/nsindiso/.local/lib/python3.6/site-packages/django/template/base.py", line 849, in _resolve_lookup
    current = current[int(bit)]
ValueError: invalid literal for int() with base 10: 'required'

During handling of the above exception, another exception occurred:

Traceback (most recent call last):
  File "/home/nsindiso/.local/lib/python3.6/site-packages/django/template/base.py", line 856, in _resolve_lookup
    (bit, current))  # missing attribute
django.template.base.VariableDoesNotExist: Failed lookup for key [required] in {'type': 'string', 'description': 'Address or hostname to access via NETCONF', 'default': ''}
[2021-04-26 16:31:16.843 DEBUG                    django.template : 878]
Exception while resolving variable 'min' in template 'ysdevices/device_form.html'.
Traceback (most recent call last):
  File "/home/nsindiso/.local/lib/python3.6/site-packages/django/template/base.py", line 835, in _resolve_lookup
    current = current[bit]
KeyError: 'min'

During handling of the above exception, another exception occurred:

Traceback (most recent call last):
  File "/home/nsindiso/.local/lib/python3.6/site-packages/django/template/base.py", line 843, in _resolve_lookup
    current = getattr(current, bit)
AttributeError: 'dict' object has no attribute 'min'

During handling of the above exception, another exception occurred:

Traceback (most recent call last):
  File "/home/nsindiso/.local/lib/python3.6/site-packages/django/template/base.py", line 849, in _resolve_lookup
    current = current[int(bit)]
ValueError: invalid literal for int() with base 10: 'min'

During handling of the above exception, another exception occurred:

Traceback (most recent call last):
  File "/home/nsindiso/.local/lib/python3.6/site-packages/django/template/base.py", line 856, in _resolve_lookup
    (bit, current))  # missing attribute
django.template.base.VariableDoesNotExist: Failed lookup for key [min] in {'type': 'string', 'description': 'Username to access the device via NETCONF', 'minLength': 1, 'maxLength': 50, 'default': ''}
[2021-04-26 16:31:16.844 DEBUG                    django.template : 878]
Exception while resolving variable 'max' in template 'ysdevices/device_form.html'.
Traceback (most recent call last):
  File "/home/nsindiso/.local/lib/python3.6/site-packages/django/template/base.py", line 835, in _resolve_lookup
    current = current[bit]
KeyError: 'max'

During handling of the above exception, another exception occurred:

Traceback (most recent call last):
  File "/home/nsindiso/.local/lib/python3.6/site-packages/django/template/base.py", line 843, in _resolve_lookup
    current = getattr(current, bit)
AttributeError: 'dict' object has no attribute 'max'

During handling of the above exception, another exception occurred:

Traceback (most recent call last):
  File "/home/nsindiso/.local/lib/python3.6/site-packages/django/template/base.py", line 849, in _resolve_lookup
    current = current[int(bit)]
ValueError: invalid literal for int() with base 10: 'max'

During handling of the above exception, another exception occurred:

Traceback (most recent call last):
  File "/home/nsindiso/.local/lib/python3.6/site-packages/django/template/base.py", line 856, in _resolve_lookup
    (bit, current))  # missing attribute
django.template.base.VariableDoesNotExist: Failed lookup for key [max] in {'type': 'string', 'description': 'Username to access the device via NETCONF', 'minLength': 1, 'maxLength': 50, 'default': ''}
[2021-04-26 16:31:16.846 DEBUG                    django.template : 878]
Exception while resolving variable 'step' in template 'ysdevices/device_form.html'.
Traceback (most recent call last):
  File "/home/nsindiso/.local/lib/python3.6/site-packages/django/template/base.py", line 835, in _resolve_lookup
    current = current[bit]
KeyError: 'step'

During handling of the above exception, another exception occurred:

Traceback (most recent call last):
  File "/home/nsindiso/.local/lib/python3.6/site-packages/django/template/base.py", line 843, in _resolve_lookup
    current = getattr(current, bit)
AttributeError: 'dict' object has no attribute 'step'

During handling of the above exception, another exception occurred:

Traceback (most recent call last):
  File "/home/nsindiso/.local/lib/python3.6/site-packages/django/template/base.py", line 849, in _resolve_lookup
    current = current[int(bit)]
ValueError: invalid literal for int() with base 10: 'step'

During handling of the above exception, another exception occurred:

Traceback (most recent call last):
  File "/home/nsindiso/.local/lib/python3.6/site-packages/django/template/base.py", line 856, in _resolve_lookup
    (bit, current))  # missing attribute
django.template.base.VariableDoesNotExist: Failed lookup for key [step] in {'type': 'string', 'description': 'Username to access the device via NETCONF', 'minLength': 1, 'maxLength': 50, 'default': ''}
[2021-04-26 16:31:16.847 DEBUG                    django.template : 878]
Exception while resolving variable 'required' in template 'ysdevices/device_form.html'.
Traceback (most recent call last):
  File "/home/nsindiso/.local/lib/python3.6/site-packages/django/template/base.py", line 835, in _resolve_lookup
    current = current[bit]
KeyError: 'required'

During handling of the above exception, another exception occurred:

Traceback (most recent call last):
  File "/home/nsindiso/.local/lib/python3.6/site-packages/django/template/base.py", line 843, in _resolve_lookup
    current = getattr(current, bit)
AttributeError: 'dict' object has no attribute 'required'

During handling of the above exception, another exception occurred:

Traceback (most recent call last):
  File "/home/nsindiso/.local/lib/python3.6/site-packages/django/template/base.py", line 849, in _resolve_lookup
    current = current[int(bit)]
ValueError: invalid literal for int() with base 10: 'required'

During handling of the above exception, another exception occurred:

Traceback (most recent call last):
  File "/home/nsindiso/.local/lib/python3.6/site-packages/django/template/base.py", line 856, in _resolve_lookup
    (bit, current))  # missing attribute
django.template.base.VariableDoesNotExist: Failed lookup for key [required] in {'type': 'string', 'description': 'Username to access the device via NETCONF', 'minLength': 1, 'maxLength': 50, 'default': ''}
[2021-04-26 16:31:16.848 DEBUG                    django.template : 878]
Exception while resolving variable 'required' in template 'ysdevices/device_form.html'.
Traceback (most recent call last):
  File "/home/nsindiso/.local/lib/python3.6/site-packages/django/template/base.py", line 835, in _resolve_lookup
    current = current[bit]
KeyError: 'required'

During handling of the above exception, another exception occurred:

Traceback (most recent call last):
  File "/home/nsindiso/.local/lib/python3.6/site-packages/django/template/base.py", line 843, in _resolve_lookup
    current = getattr(current, bit)
AttributeError: 'dict' object has no attribute 'required'

During handling of the above exception, another exception occurred:

Traceback (most recent call last):
  File "/home/nsindiso/.local/lib/python3.6/site-packages/django/template/base.py", line 849, in _resolve_lookup
    current = current[int(bit)]
ValueError: invalid literal for int() with base 10: 'required'

During handling of the above exception, another exception occurred:

Traceback (most recent call last):
  File "/home/nsindiso/.local/lib/python3.6/site-packages/django/template/base.py", line 856, in _resolve_lookup
    (bit, current))  # missing attribute
django.template.base.VariableDoesNotExist: Failed lookup for key [required] in {'type': 'string', 'description': 'Username to access the device via NETCONF', 'minLength': 1, 'maxLength': 50, 'default': ''}
[2021-04-26 16:31:16.849 DEBUG                    django.template : 878]
Exception while resolving variable 'label' in template 'ysdevices/device_form.html'.
Traceback (most recent call last):
  File "/home/nsindiso/.local/lib/python3.6/site-packages/django/template/base.py", line 835, in _resolve_lookup
    current = current[bit]
KeyError: 'label'

During handling of the above exception, another exception occurred:

Traceback (most recent call last):
  File "/home/nsindiso/.local/lib/python3.6/site-packages/django/template/base.py", line 843, in _resolve_lookup
    current = getattr(current, bit)
AttributeError: 'dict' object has no attribute 'label'

During handling of the above exception, another exception occurred:

Traceback (most recent call last):
  File "/home/nsindiso/.local/lib/python3.6/site-packages/django/template/base.py", line 849, in _resolve_lookup
    current = current[int(bit)]
ValueError: invalid literal for int() with base 10: 'label'

During handling of the above exception, another exception occurred:

Traceback (most recent call last):
  File "/home/nsindiso/.local/lib/python3.6/site-packages/django/template/base.py", line 856, in _resolve_lookup
    (bit, current))  # missing attribute
django.template.base.VariableDoesNotExist: Failed lookup for key [label] in {'type': 'string', 'description': 'Username to access the device via NETCONF', 'minLength': 1, 'maxLength': 50, 'default': ''}
[2021-04-26 16:31:16.850 DEBUG                    django.template : 878]
Exception while resolving variable 'required' in template 'ysdevices/device_form.html'.
Traceback (most recent call last):
  File "/home/nsindiso/.local/lib/python3.6/site-packages/django/template/base.py", line 835, in _resolve_lookup
    current = current[bit]
KeyError: 'required'

During handling of the above exception, another exception occurred:

Traceback (most recent call last):
  File "/home/nsindiso/.local/lib/python3.6/site-packages/django/template/base.py", line 843, in _resolve_lookup
    current = getattr(current, bit)
AttributeError: 'dict' object has no attribute 'required'

During handling of the above exception, another exception occurred:

Traceback (most recent call last):
  File "/home/nsindiso/.local/lib/python3.6/site-packages/django/template/base.py", line 849, in _resolve_lookup
    current = current[int(bit)]
ValueError: invalid literal for int() with base 10: 'required'

During handling of the above exception, another exception occurred:

Traceback (most recent call last):
  File "/home/nsindiso/.local/lib/python3.6/site-packages/django/template/base.py", line 856, in _resolve_lookup
    (bit, current))  # missing attribute
django.template.base.VariableDoesNotExist: Failed lookup for key [required] in {'type': 'string', 'description': 'Username to access the device via NETCONF', 'minLength': 1, 'maxLength': 50, 'default': ''}
[2021-04-26 16:31:16.851 DEBUG                    django.template : 878]
Exception while resolving variable 'min' in template 'ysdevices/device_form.html'.
Traceback (most recent call last):
  File "/home/nsindiso/.local/lib/python3.6/site-packages/django/template/base.py", line 835, in _resolve_lookup
    current = current[bit]
KeyError: 'min'

During handling of the above exception, another exception occurred:

Traceback (most recent call last):
  File "/home/nsindiso/.local/lib/python3.6/site-packages/django/template/base.py", line 843, in _resolve_lookup
    current = getattr(current, bit)
AttributeError: 'dict' object has no attribute 'min'

During handling of the above exception, another exception occurred:

Traceback (most recent call last):
  File "/home/nsindiso/.local/lib/python3.6/site-packages/django/template/base.py", line 849, in _resolve_lookup
    current = current[int(bit)]
ValueError: invalid literal for int() with base 10: 'min'

During handling of the above exception, another exception occurred:

Traceback (most recent call last):
  File "/home/nsindiso/.local/lib/python3.6/site-packages/django/template/base.py", line 856, in _resolve_lookup
    (bit, current))  # missing attribute
django.template.base.VariableDoesNotExist: Failed lookup for key [min] in {'type': 'password', 'description': 'Password to access the device via NETCONF', 'minLength': 1, 'maxLength': 50}
[2021-04-26 16:31:16.852 DEBUG                    django.template : 878]
Exception while resolving variable 'max' in template 'ysdevices/device_form.html'.
Traceback (most recent call last):
  File "/home/nsindiso/.local/lib/python3.6/site-packages/django/template/base.py", line 835, in _resolve_lookup
    current = current[bit]
KeyError: 'max'

During handling of the above exception, another exception occurred:

Traceback (most recent call last):
  File "/home/nsindiso/.local/lib/python3.6/site-packages/django/template/base.py", line 843, in _resolve_lookup
    current = getattr(current, bit)
AttributeError: 'dict' object has no attribute 'max'

During handling of the above exception, another exception occurred:

Traceback (most recent call last):
  File "/home/nsindiso/.local/lib/python3.6/site-packages/django/template/base.py", line 849, in _resolve_lookup
    current = current[int(bit)]
ValueError: invalid literal for int() with base 10: 'max'

During handling of the above exception, another exception occurred:

Traceback (most recent call last):
  File "/home/nsindiso/.local/lib/python3.6/site-packages/django/template/base.py", line 856, in _resolve_lookup
    (bit, current))  # missing attribute
django.template.base.VariableDoesNotExist: Failed lookup for key [max] in {'type': 'password', 'description': 'Password to access the device via NETCONF', 'minLength': 1, 'maxLength': 50}
[2021-04-26 16:31:16.853 DEBUG                    django.template : 878]
Exception while resolving variable 'step' in template 'ysdevices/device_form.html'.
Traceback (most recent call last):
  File "/home/nsindiso/.local/lib/python3.6/site-packages/django/template/base.py", line 835, in _resolve_lookup
    current = current[bit]
KeyError: 'step'

During handling of the above exception, another exception occurred:

Traceback (most recent call last):
  File "/home/nsindiso/.local/lib/python3.6/site-packages/django/template/base.py", line 843, in _resolve_lookup
    current = getattr(current, bit)
AttributeError: 'dict' object has no attribute 'step'

During handling of the above exception, another exception occurred:

Traceback (most recent call last):
  File "/home/nsindiso/.local/lib/python3.6/site-packages/django/template/base.py", line 849, in _resolve_lookup
    current = current[int(bit)]
ValueError: invalid literal for int() with base 10: 'step'

During handling of the above exception, another exception occurred:

Traceback (most recent call last):
  File "/home/nsindiso/.local/lib/python3.6/site-packages/django/template/base.py", line 856, in _resolve_lookup
    (bit, current))  # missing attribute
django.template.base.VariableDoesNotExist: Failed lookup for key [step] in {'type': 'password', 'description': 'Password to access the device via NETCONF', 'minLength': 1, 'maxLength': 50}
[2021-04-26 16:31:16.853 DEBUG                    django.template : 878]
Exception while resolving variable 'default' in template 'ysdevices/device_form.html'.
Traceback (most recent call last):
  File "/home/nsindiso/.local/lib/python3.6/site-packages/django/template/base.py", line 835, in _resolve_lookup
    current = current[bit]
KeyError: 'default'

During handling of the above exception, another exception occurred:

Traceback (most recent call last):
  File "/home/nsindiso/.local/lib/python3.6/site-packages/django/template/base.py", line 843, in _resolve_lookup
    current = getattr(current, bit)
AttributeError: 'dict' object has no attribute 'default'

During handling of the above exception, another exception occurred:

Traceback (most recent call last):
  File "/home/nsindiso/.local/lib/python3.6/site-packages/django/template/base.py", line 849, in _resolve_lookup
    current = current[int(bit)]
ValueError: invalid literal for int() with base 10: 'default'

During handling of the above exception, another exception occurred:

Traceback (most recent call last):
  File "/home/nsindiso/.local/lib/python3.6/site-packages/django/template/base.py", line 856, in _resolve_lookup
    (bit, current))  # missing attribute
django.template.base.VariableDoesNotExist: Failed lookup for key [default] in {'type': 'password', 'description': 'Password to access the device via NETCONF', 'minLength': 1, 'maxLength': 50}
[2021-04-26 16:31:16.854 DEBUG                    django.template : 878]
Exception while resolving variable 'default' in template 'ysdevices/device_form.html'.
Traceback (most recent call last):
  File "/home/nsindiso/.local/lib/python3.6/site-packages/django/template/base.py", line 835, in _resolve_lookup
    current = current[bit]
KeyError: 'default'

During handling of the above exception, another exception occurred:

Traceback (most recent call last):
  File "/home/nsindiso/.local/lib/python3.6/site-packages/django/template/base.py", line 843, in _resolve_lookup
    current = getattr(current, bit)
AttributeError: 'dict' object has no attribute 'default'

During handling of the above exception, another exception occurred:

Traceback (most recent call last):
  File "/home/nsindiso/.local/lib/python3.6/site-packages/django/template/base.py", line 849, in _resolve_lookup
    current = current[int(bit)]
ValueError: invalid literal for int() with base 10: 'default'

During handling of the above exception, another exception occurred:

Traceback (most recent call last):
  File "/home/nsindiso/.local/lib/python3.6/site-packages/django/template/base.py", line 856, in _resolve_lookup
    (bit, current))  # missing attribute
django.template.base.VariableDoesNotExist: Failed lookup for key [default] in {'type': 'password', 'description': 'Password to access the device via NETCONF', 'minLength': 1, 'maxLength': 50}
[2021-04-26 16:31:16.855 DEBUG                    django.template : 878]
Exception while resolving variable 'required' in template 'ysdevices/device_form.html'.
Traceback (most recent call last):
  File "/home/nsindiso/.local/lib/python3.6/site-packages/django/template/base.py", line 835, in _resolve_lookup
    current = current[bit]
KeyError: 'required'

During handling of the above exception, another exception occurred:

Traceback (most recent call last):
  File "/home/nsindiso/.local/lib/python3.6/site-packages/django/template/base.py", line 843, in _resolve_lookup
    current = getattr(current, bit)
AttributeError: 'dict' object has no attribute 'required'

During handling of the above exception, another exception occurred:

Traceback (most recent call last):
  File "/home/nsindiso/.local/lib/python3.6/site-packages/django/template/base.py", line 849, in _resolve_lookup
    current = current[int(bit)]
ValueError: invalid literal for int() with base 10: 'required'

During handling of the above exception, another exception occurred:

Traceback (most recent call last):
  File "/home/nsindiso/.local/lib/python3.6/site-packages/django/template/base.py", line 856, in _resolve_lookup
    (bit, current))  # missing attribute
django.template.base.VariableDoesNotExist: Failed lookup for key [required] in {'type': 'password', 'description': 'Password to access the device via NETCONF', 'minLength': 1, 'maxLength': 50}
[2021-04-26 16:31:16.856 DEBUG                    django.template : 878]
Exception while resolving variable 'required' in template 'ysdevices/device_form.html'.
Traceback (most recent call last):
  File "/home/nsindiso/.local/lib/python3.6/site-packages/django/template/base.py", line 835, in _resolve_lookup
    current = current[bit]
KeyError: 'required'

During handling of the above exception, another exception occurred:

Traceback (most recent call last):
  File "/home/nsindiso/.local/lib/python3.6/site-packages/django/template/base.py", line 843, in _resolve_lookup
    current = getattr(current, bit)
AttributeError: 'dict' object has no attribute 'required'

During handling of the above exception, another exception occurred:

Traceback (most recent call last):
  File "/home/nsindiso/.local/lib/python3.6/site-packages/django/template/base.py", line 849, in _resolve_lookup
    current = current[int(bit)]
ValueError: invalid literal for int() with base 10: 'required'

During handling of the above exception, another exception occurred:

Traceback (most recent call last):
  File "/home/nsindiso/.local/lib/python3.6/site-packages/django/template/base.py", line 856, in _resolve_lookup
    (bit, current))  # missing attribute
django.template.base.VariableDoesNotExist: Failed lookup for key [required] in {'type': 'password', 'description': 'Password to access the device via NETCONF', 'minLength': 1, 'maxLength': 50}
[2021-04-26 16:31:16.857 DEBUG                    django.template : 878]
Exception while resolving variable 'label' in template 'ysdevices/device_form.html'.
Traceback (most recent call last):
  File "/home/nsindiso/.local/lib/python3.6/site-packages/django/template/base.py", line 835, in _resolve_lookup
    current = current[bit]
KeyError: 'label'

During handling of the above exception, another exception occurred:

Traceback (most recent call last):
  File "/home/nsindiso/.local/lib/python3.6/site-packages/django/template/base.py", line 843, in _resolve_lookup
    current = getattr(current, bit)
AttributeError: 'dict' object has no attribute 'label'

During handling of the above exception, another exception occurred:

Traceback (most recent call last):
  File "/home/nsindiso/.local/lib/python3.6/site-packages/django/template/base.py", line 849, in _resolve_lookup
    current = current[int(bit)]
ValueError: invalid literal for int() with base 10: 'label'

During handling of the above exception, another exception occurred:

Traceback (most recent call last):
  File "/home/nsindiso/.local/lib/python3.6/site-packages/django/template/base.py", line 856, in _resolve_lookup
    (bit, current))  # missing attribute
django.template.base.VariableDoesNotExist: Failed lookup for key [label] in {'type': 'password', 'description': 'Password to access the device via NETCONF', 'minLength': 1, 'maxLength': 50}
[2021-04-26 16:31:16.858 DEBUG                    django.template : 878]
Exception while resolving variable 'required' in template 'ysdevices/device_form.html'.
Traceback (most recent call last):
  File "/home/nsindiso/.local/lib/python3.6/site-packages/django/template/base.py", line 835, in _resolve_lookup
    current = current[bit]
KeyError: 'required'

During handling of the above exception, another exception occurred:

Traceback (most recent call last):
  File "/home/nsindiso/.local/lib/python3.6/site-packages/django/template/base.py", line 843, in _resolve_lookup
    current = getattr(current, bit)
AttributeError: 'dict' object has no attribute 'required'

During handling of the above exception, another exception occurred:

Traceback (most recent call last):
  File "/home/nsindiso/.local/lib/python3.6/site-packages/django/template/base.py", line 849, in _resolve_lookup
    current = current[int(bit)]
ValueError: invalid literal for int() with base 10: 'required'

During handling of the above exception, another exception occurred:

Traceback (most recent call last):
  File "/home/nsindiso/.local/lib/python3.6/site-packages/django/template/base.py", line 856, in _resolve_lookup
    (bit, current))  # missing attribute
django.template.base.VariableDoesNotExist: Failed lookup for key [required] in {'type': 'password', 'description': 'Password to access the device via NETCONF', 'minLength': 1, 'maxLength': 50}
[2021-04-26 16:31:16.860 DEBUG                    django.template : 878]
Exception while resolving variable 'minLength' in template 'ysdevices/device_form.html'.
Traceback (most recent call last):
  File "/home/nsindiso/.local/lib/python3.6/site-packages/django/template/base.py", line 835, in _resolve_lookup
    current = current[bit]
KeyError: 'minLength'

During handling of the above exception, another exception occurred:

Traceback (most recent call last):
  File "/home/nsindiso/.local/lib/python3.6/site-packages/django/template/base.py", line 843, in _resolve_lookup
    current = getattr(current, bit)
AttributeError: 'dict' object has no attribute 'minLength'

During handling of the above exception, another exception occurred:

Traceback (most recent call last):
  File "/home/nsindiso/.local/lib/python3.6/site-packages/django/template/base.py", line 849, in _resolve_lookup
    current = current[int(bit)]
ValueError: invalid literal for int() with base 10: 'minLength'

During handling of the above exception, another exception occurred:

Traceback (most recent call last):
  File "/home/nsindiso/.local/lib/python3.6/site-packages/django/template/base.py", line 856, in _resolve_lookup
    (bit, current))  # missing attribute
django.template.base.VariableDoesNotExist: Failed lookup for key [minLength] in {'type': 'int', 'description': 'Timeout, in seconds, for NETCONF requests', 'min': 0, 'default': ''}
[2021-04-26 16:31:16.861 DEBUG                    django.template : 878]
Exception while resolving variable 'max' in template 'ysdevices/device_form.html'.
Traceback (most recent call last):
  File "/home/nsindiso/.local/lib/python3.6/site-packages/django/template/base.py", line 835, in _resolve_lookup
    current = current[bit]
KeyError: 'max'

During handling of the above exception, another exception occurred:

Traceback (most recent call last):
  File "/home/nsindiso/.local/lib/python3.6/site-packages/django/template/base.py", line 843, in _resolve_lookup
    current = getattr(current, bit)
AttributeError: 'dict' object has no attribute 'max'

During handling of the above exception, another exception occurred:

Traceback (most recent call last):
  File "/home/nsindiso/.local/lib/python3.6/site-packages/django/template/base.py", line 849, in _resolve_lookup
    current = current[int(bit)]
ValueError: invalid literal for int() with base 10: 'max'

During handling of the above exception, another exception occurred:

Traceback (most recent call last):
  File "/home/nsindiso/.local/lib/python3.6/site-packages/django/template/base.py", line 856, in _resolve_lookup
    (bit, current))  # missing attribute
django.template.base.VariableDoesNotExist: Failed lookup for key [max] in {'type': 'int', 'description': 'Timeout, in seconds, for NETCONF requests', 'min': 0, 'default': ''}
[2021-04-26 16:31:16.861 DEBUG                    django.template : 878]
Exception while resolving variable 'maxLength' in template 'ysdevices/device_form.html'.
Traceback (most recent call last):
  File "/home/nsindiso/.local/lib/python3.6/site-packages/django/template/base.py", line 835, in _resolve_lookup
    current = current[bit]
KeyError: 'maxLength'

During handling of the above exception, another exception occurred:

Traceback (most recent call last):
  File "/home/nsindiso/.local/lib/python3.6/site-packages/django/template/base.py", line 843, in _resolve_lookup
    current = getattr(current, bit)
AttributeError: 'dict' object has no attribute 'maxLength'

During handling of the above exception, another exception occurred:

Traceback (most recent call last):
  File "/home/nsindiso/.local/lib/python3.6/site-packages/django/template/base.py", line 849, in _resolve_lookup
    current = current[int(bit)]
ValueError: invalid literal for int() with base 10: 'maxLength'

During handling of the above exception, another exception occurred:

Traceback (most recent call last):
  File "/home/nsindiso/.local/lib/python3.6/site-packages/django/template/base.py", line 856, in _resolve_lookup
    (bit, current))  # missing attribute
django.template.base.VariableDoesNotExist: Failed lookup for key [maxLength] in {'type': 'int', 'description': 'Timeout, in seconds, for NETCONF requests', 'min': 0, 'default': ''}
[2021-04-26 16:31:16.862 DEBUG                    django.template : 878]
Exception while resolving variable 'step' in template 'ysdevices/device_form.html'.
Traceback (most recent call last):
  File "/home/nsindiso/.local/lib/python3.6/site-packages/django/template/base.py", line 835, in _resolve_lookup
    current = current[bit]
KeyError: 'step'

During handling of the above exception, another exception occurred:

Traceback (most recent call last):
  File "/home/nsindiso/.local/lib/python3.6/site-packages/django/template/base.py", line 843, in _resolve_lookup
    current = getattr(current, bit)
AttributeError: 'dict' object has no attribute 'step'

During handling of the above exception, another exception occurred:

Traceback (most recent call last):
  File "/home/nsindiso/.local/lib/python3.6/site-packages/django/template/base.py", line 849, in _resolve_lookup
    current = current[int(bit)]
ValueError: invalid literal for int() with base 10: 'step'

During handling of the above exception, another exception occurred:

Traceback (most recent call last):
  File "/home/nsindiso/.local/lib/python3.6/site-packages/django/template/base.py", line 856, in _resolve_lookup
    (bit, current))  # missing attribute
django.template.base.VariableDoesNotExist: Failed lookup for key [step] in {'type': 'int', 'description': 'Timeout, in seconds, for NETCONF requests', 'min': 0, 'default': ''}
[2021-04-26 16:31:16.863 DEBUG                    django.template : 878]
Exception while resolving variable 'required' in template 'ysdevices/device_form.html'.
Traceback (most recent call last):
  File "/home/nsindiso/.local/lib/python3.6/site-packages/django/template/base.py", line 835, in _resolve_lookup
    current = current[bit]
KeyError: 'required'

During handling of the above exception, another exception occurred:

Traceback (most recent call last):
  File "/home/nsindiso/.local/lib/python3.6/site-packages/django/template/base.py", line 843, in _resolve_lookup
    current = getattr(current, bit)
AttributeError: 'dict' object has no attribute 'required'

During handling of the above exception, another exception occurred:

Traceback (most recent call last):
  File "/home/nsindiso/.local/lib/python3.6/site-packages/django/template/base.py", line 849, in _resolve_lookup
    current = current[int(bit)]
ValueError: invalid literal for int() with base 10: 'required'

During handling of the above exception, another exception occurred:

Traceback (most recent call last):
  File "/home/nsindiso/.local/lib/python3.6/site-packages/django/template/base.py", line 856, in _resolve_lookup
    (bit, current))  # missing attribute
django.template.base.VariableDoesNotExist: Failed lookup for key [required] in {'type': 'int', 'description': 'Timeout, in seconds, for NETCONF requests', 'min': 0, 'default': ''}
[2021-04-26 16:31:16.864 DEBUG                    django.template : 878]
Exception while resolving variable 'required' in template 'ysdevices/device_form.html'.
Traceback (most recent call last):
  File "/home/nsindiso/.local/lib/python3.6/site-packages/django/template/base.py", line 835, in _resolve_lookup
    current = current[bit]
KeyError: 'required'

During handling of the above exception, another exception occurred:

Traceback (most recent call last):
  File "/home/nsindiso/.local/lib/python3.6/site-packages/django/template/base.py", line 843, in _resolve_lookup
    current = getattr(current, bit)
AttributeError: 'dict' object has no attribute 'required'

During handling of the above exception, another exception occurred:

Traceback (most recent call last):
  File "/home/nsindiso/.local/lib/python3.6/site-packages/django/template/base.py", line 849, in _resolve_lookup
    current = current[int(bit)]
ValueError: invalid literal for int() with base 10: 'required'

During handling of the above exception, another exception occurred:

Traceback (most recent call last):
  File "/home/nsindiso/.local/lib/python3.6/site-packages/django/template/base.py", line 856, in _resolve_lookup
    (bit, current))  # missing attribute
django.template.base.VariableDoesNotExist: Failed lookup for key [required] in {'type': 'int', 'description': 'Timeout, in seconds, for NETCONF requests', 'min': 0, 'default': ''}
[2021-04-26 16:31:16.866 DEBUG                    django.template : 878]
Exception while resolving variable 'label' in template 'ysdevices/device_form.html'.
Traceback (most recent call last):
  File "/home/nsindiso/.local/lib/python3.6/site-packages/django/template/base.py", line 835, in _resolve_lookup
    current = current[bit]
KeyError: 'label'

During handling of the above exception, another exception occurred:

Traceback (most recent call last):
  File "/home/nsindiso/.local/lib/python3.6/site-packages/django/template/base.py", line 843, in _resolve_lookup
    current = getattr(current, bit)
AttributeError: 'dict' object has no attribute 'label'

During handling of the above exception, another exception occurred:

Traceback (most recent call last):
  File "/home/nsindiso/.local/lib/python3.6/site-packages/django/template/base.py", line 849, in _resolve_lookup
    current = current[int(bit)]
ValueError: invalid literal for int() with base 10: 'label'

During handling of the above exception, another exception occurred:

Traceback (most recent call last):
  File "/home/nsindiso/.local/lib/python3.6/site-packages/django/template/base.py", line 856, in _resolve_lookup
    (bit, current))  # missing attribute
django.template.base.VariableDoesNotExist: Failed lookup for key [label] in {'type': 'int', 'description': 'Timeout, in seconds, for NETCONF requests', 'min': 0, 'default': ''}
[2021-04-26 16:31:16.867 DEBUG                    django.template : 878]
Exception while resolving variable 'required' in template 'ysdevices/device_form.html'.
Traceback (most recent call last):
  File "/home/nsindiso/.local/lib/python3.6/site-packages/django/template/base.py", line 835, in _resolve_lookup
    current = current[bit]
KeyError: 'required'

During handling of the above exception, another exception occurred:

Traceback (most recent call last):
  File "/home/nsindiso/.local/lib/python3.6/site-packages/django/template/base.py", line 843, in _resolve_lookup
    current = getattr(current, bit)
AttributeError: 'dict' object has no attribute 'required'

During handling of the above exception, another exception occurred:

Traceback (most recent call last):
  File "/home/nsindiso/.local/lib/python3.6/site-packages/django/template/base.py", line 849, in _resolve_lookup
    current = current[int(bit)]
ValueError: invalid literal for int() with base 10: 'required'

During handling of the above exception, another exception occurred:

Traceback (most recent call last):
  File "/home/nsindiso/.local/lib/python3.6/site-packages/django/template/base.py", line 856, in _resolve_lookup
    (bit, current))  # missing attribute
django.template.base.VariableDoesNotExist: Failed lookup for key [required] in {'type': 'int', 'description': 'Timeout, in seconds, for NETCONF requests', 'min': 0, 'default': ''}
[2021-04-26 16:31:16.869 DEBUG                    django.template : 878]
Exception while resolving variable 'description' in template 'ysdevices/device_form.html'.
Traceback (most recent call last):
  File "/home/nsindiso/.local/lib/python3.6/site-packages/django/template/base.py", line 835, in _resolve_lookup
    current = current[bit]
KeyError: 'description'

During handling of the above exception, another exception occurred:

Traceback (most recent call last):
  File "/home/nsindiso/.local/lib/python3.6/site-packages/django/template/base.py", line 843, in _resolve_lookup
    current = getattr(current, bit)
AttributeError: 'dict' object has no attribute 'description'

During handling of the above exception, another exception occurred:

Traceback (most recent call last):
  File "/home/nsindiso/.local/lib/python3.6/site-packages/django/template/base.py", line 849, in _resolve_lookup
    current = current[int(bit)]
ValueError: invalid literal for int() with base 10: 'description'

During handling of the above exception, another exception occurred:

Traceback (most recent call last):
  File "/home/nsindiso/.local/lib/python3.6/site-packages/django/template/base.py", line 856, in _resolve_lookup
    (bit, current))  # missing attribute
django.template.base.VariableDoesNotExist: Failed lookup for key [description] in {'label': 'Device allows SSH login', 'type': 'boolean', 'default': False}
[2021-04-26 16:31:16.877 DEBUG                    django.template : 878]
Exception while resolving variable 'min' in template 'ysdevices/device_form.html'.
Traceback (most recent call last):
  File "/home/nsindiso/.local/lib/python3.6/site-packages/django/template/base.py", line 835, in _resolve_lookup
    current = current[bit]
KeyError: 'min'

During handling of the above exception, another exception occurred:

Traceback (most recent call last):
  File "/home/nsindiso/.local/lib/python3.6/site-packages/django/template/base.py", line 843, in _resolve_lookup
    current = getattr(current, bit)
AttributeError: 'dict' object has no attribute 'min'

During handling of the above exception, another exception occurred:

Traceback (most recent call last):
  File "/home/nsindiso/.local/lib/python3.6/site-packages/django/template/base.py", line 849, in _resolve_lookup
    current = current[int(bit)]
ValueError: invalid literal for int() with base 10: 'min'

During handling of the above exception, another exception occurred:

Traceback (most recent call last):
  File "/home/nsindiso/.local/lib/python3.6/site-packages/django/template/base.py", line 856, in _resolve_lookup
    (bit, current))  # missing attribute
django.template.base.VariableDoesNotExist: Failed lookup for key [min] in {'type': 'string', 'description': 'Address or hostname to access via SSH', 'default': ''}
[2021-04-26 16:31:16.878 DEBUG                    django.template : 878]
Exception while resolving variable 'minLength' in template 'ysdevices/device_form.html'.
Traceback (most recent call last):
  File "/home/nsindiso/.local/lib/python3.6/site-packages/django/template/base.py", line 835, in _resolve_lookup
    current = current[bit]
KeyError: 'minLength'

During handling of the above exception, another exception occurred:

Traceback (most recent call last):
  File "/home/nsindiso/.local/lib/python3.6/site-packages/django/template/base.py", line 843, in _resolve_lookup
    current = getattr(current, bit)
AttributeError: 'dict' object has no attribute 'minLength'

During handling of the above exception, another exception occurred:

Traceback (most recent call last):
  File "/home/nsindiso/.local/lib/python3.6/site-packages/django/template/base.py", line 849, in _resolve_lookup
    current = current[int(bit)]
ValueError: invalid literal for int() with base 10: 'minLength'

During handling of the above exception, another exception occurred:

Traceback (most recent call last):
  File "/home/nsindiso/.local/lib/python3.6/site-packages/django/template/base.py", line 856, in _resolve_lookup
    (bit, current))  # missing attribute
django.template.base.VariableDoesNotExist: Failed lookup for key [minLength] in {'type': 'string', 'description': 'Address or hostname to access via SSH', 'default': ''}
[2021-04-26 16:31:16.879 DEBUG                    django.template : 878]
Exception while resolving variable 'max' in template 'ysdevices/device_form.html'.
Traceback (most recent call last):
  File "/home/nsindiso/.local/lib/python3.6/site-packages/django/template/base.py", line 835, in _resolve_lookup
    current = current[bit]
KeyError: 'max'

During handling of the above exception, another exception occurred:

Traceback (most recent call last):
  File "/home/nsindiso/.local/lib/python3.6/site-packages/django/template/base.py", line 843, in _resolve_lookup
    current = getattr(current, bit)
AttributeError: 'dict' object has no attribute 'max'

During handling of the above exception, another exception occurred:

Traceback (most recent call last):
  File "/home/nsindiso/.local/lib/python3.6/site-packages/django/template/base.py", line 849, in _resolve_lookup
    current = current[int(bit)]
ValueError: invalid literal for int() with base 10: 'max'

During handling of the above exception, another exception occurred:

Traceback (most recent call last):
  File "/home/nsindiso/.local/lib/python3.6/site-packages/django/template/base.py", line 856, in _resolve_lookup
    (bit, current))  # missing attribute
django.template.base.VariableDoesNotExist: Failed lookup for key [max] in {'type': 'string', 'description': 'Address or hostname to access via SSH', 'default': ''}
[2021-04-26 16:31:16.880 DEBUG                    django.template : 878]
Exception while resolving variable 'maxLength' in template 'ysdevices/device_form.html'.
Traceback (most recent call last):
  File "/home/nsindiso/.local/lib/python3.6/site-packages/django/template/base.py", line 835, in _resolve_lookup
    current = current[bit]
KeyError: 'maxLength'

During handling of the above exception, another exception occurred:

Traceback (most recent call last):
  File "/home/nsindiso/.local/lib/python3.6/site-packages/django/template/base.py", line 843, in _resolve_lookup
    current = getattr(current, bit)
AttributeError: 'dict' object has no attribute 'maxLength'

During handling of the above exception, another exception occurred:

Traceback (most recent call last):
  File "/home/nsindiso/.local/lib/python3.6/site-packages/django/template/base.py", line 849, in _resolve_lookup
    current = current[int(bit)]
ValueError: invalid literal for int() with base 10: 'maxLength'

During handling of the above exception, another exception occurred:

Traceback (most recent call last):
  File "/home/nsindiso/.local/lib/python3.6/site-packages/django/template/base.py", line 856, in _resolve_lookup
    (bit, current))  # missing attribute
django.template.base.VariableDoesNotExist: Failed lookup for key [maxLength] in {'type': 'string', 'description': 'Address or hostname to access via SSH', 'default': ''}
[2021-04-26 16:31:16.881 DEBUG                    django.template : 878]
Exception while resolving variable 'step' in template 'ysdevices/device_form.html'.
Traceback (most recent call last):
  File "/home/nsindiso/.local/lib/python3.6/site-packages/django/template/base.py", line 835, in _resolve_lookup
    current = current[bit]
KeyError: 'step'

During handling of the above exception, another exception occurred:

Traceback (most recent call last):
  File "/home/nsindiso/.local/lib/python3.6/site-packages/django/template/base.py", line 843, in _resolve_lookup
    current = getattr(current, bit)
AttributeError: 'dict' object has no attribute 'step'

During handling of the above exception, another exception occurred:

Traceback (most recent call last):
  File "/home/nsindiso/.local/lib/python3.6/site-packages/django/template/base.py", line 849, in _resolve_lookup
    current = current[int(bit)]
ValueError: invalid literal for int() with base 10: 'step'

During handling of the above exception, another exception occurred:

Traceback (most recent call last):
  File "/home/nsindiso/.local/lib/python3.6/site-packages/django/template/base.py", line 856, in _resolve_lookup
    (bit, current))  # missing attribute
django.template.base.VariableDoesNotExist: Failed lookup for key [step] in {'type': 'string', 'description': 'Address or hostname to access via SSH', 'default': ''}
[2021-04-26 16:31:16.882 DEBUG                    django.template : 878]
Exception while resolving variable 'required' in template 'ysdevices/device_form.html'.
Traceback (most recent call last):
  File "/home/nsindiso/.local/lib/python3.6/site-packages/django/template/base.py", line 835, in _resolve_lookup
    current = current[bit]
KeyError: 'required'

During handling of the above exception, another exception occurred:

Traceback (most recent call last):
  File "/home/nsindiso/.local/lib/python3.6/site-packages/django/template/base.py", line 843, in _resolve_lookup
    current = getattr(current, bit)
AttributeError: 'dict' object has no attribute 'required'

During handling of the above exception, another exception occurred:

Traceback (most recent call last):
  File "/home/nsindiso/.local/lib/python3.6/site-packages/django/template/base.py", line 849, in _resolve_lookup
    current = current[int(bit)]
ValueError: invalid literal for int() with base 10: 'required'

During handling of the above exception, another exception occurred:

Traceback (most recent call last):
  File "/home/nsindiso/.local/lib/python3.6/site-packages/django/template/base.py", line 856, in _resolve_lookup
    (bit, current))  # missing attribute
django.template.base.VariableDoesNotExist: Failed lookup for key [required] in {'type': 'string', 'description': 'Address or hostname to access via SSH', 'default': ''}
[2021-04-26 16:31:16.883 DEBUG                    django.template : 878]
Exception while resolving variable 'required' in template 'ysdevices/device_form.html'.
Traceback (most recent call last):
  File "/home/nsindiso/.local/lib/python3.6/site-packages/django/template/base.py", line 835, in _resolve_lookup
    current = current[bit]
KeyError: 'required'

During handling of the above exception, another exception occurred:

Traceback (most recent call last):
  File "/home/nsindiso/.local/lib/python3.6/site-packages/django/template/base.py", line 843, in _resolve_lookup
    current = getattr(current, bit)
AttributeError: 'dict' object has no attribute 'required'

During handling of the above exception, another exception occurred:

Traceback (most recent call last):
  File "/home/nsindiso/.local/lib/python3.6/site-packages/django/template/base.py", line 849, in _resolve_lookup
    current = current[int(bit)]
ValueError: invalid literal for int() with base 10: 'required'

During handling of the above exception, another exception occurred:

Traceback (most recent call last):
  File "/home/nsindiso/.local/lib/python3.6/site-packages/django/template/base.py", line 856, in _resolve_lookup
    (bit, current))  # missing attribute
django.template.base.VariableDoesNotExist: Failed lookup for key [required] in {'type': 'string', 'description': 'Address or hostname to access via SSH', 'default': ''}
[2021-04-26 16:31:16.884 DEBUG                    django.template : 878]
Exception while resolving variable 'label' in template 'ysdevices/device_form.html'.
Traceback (most recent call last):
  File "/home/nsindiso/.local/lib/python3.6/site-packages/django/template/base.py", line 835, in _resolve_lookup
    current = current[bit]
KeyError: 'label'

During handling of the above exception, another exception occurred:

Traceback (most recent call last):
  File "/home/nsindiso/.local/lib/python3.6/site-packages/django/template/base.py", line 843, in _resolve_lookup
    current = getattr(current, bit)
AttributeError: 'dict' object has no attribute 'label'

During handling of the above exception, another exception occurred:

Traceback (most recent call last):
  File "/home/nsindiso/.local/lib/python3.6/site-packages/django/template/base.py", line 849, in _resolve_lookup
    current = current[int(bit)]
ValueError: invalid literal for int() with base 10: 'label'

During handling of the above exception, another exception occurred:

Traceback (most recent call last):
  File "/home/nsindiso/.local/lib/python3.6/site-packages/django/template/base.py", line 856, in _resolve_lookup
    (bit, current))  # missing attribute
django.template.base.VariableDoesNotExist: Failed lookup for key [label] in {'type': 'string', 'description': 'Address or hostname to access via SSH', 'default': ''}
[2021-04-26 16:31:16.884 DEBUG                    django.template : 878]
Exception while resolving variable 'required' in template 'ysdevices/device_form.html'.
Traceback (most recent call last):
  File "/home/nsindiso/.local/lib/python3.6/site-packages/django/template/base.py", line 835, in _resolve_lookup
    current = current[bit]
KeyError: 'required'

During handling of the above exception, another exception occurred:

Traceback (most recent call last):
  File "/home/nsindiso/.local/lib/python3.6/site-packages/django/template/base.py", line 843, in _resolve_lookup
    current = getattr(current, bit)
AttributeError: 'dict' object has no attribute 'required'

During handling of the above exception, another exception occurred:

Traceback (most recent call last):
  File "/home/nsindiso/.local/lib/python3.6/site-packages/django/template/base.py", line 849, in _resolve_lookup
    current = current[int(bit)]
ValueError: invalid literal for int() with base 10: 'required'

During handling of the above exception, another exception occurred:

Traceback (most recent call last):
  File "/home/nsindiso/.local/lib/python3.6/site-packages/django/template/base.py", line 856, in _resolve_lookup
    (bit, current))  # missing attribute
django.template.base.VariableDoesNotExist: Failed lookup for key [required] in {'type': 'string', 'description': 'Address or hostname to access via SSH', 'default': ''}
[2021-04-26 16:31:16.886 DEBUG                    django.template : 878]
Exception while resolving variable 'minLength' in template 'ysdevices/device_form.html'.
Traceback (most recent call last):
  File "/home/nsindiso/.local/lib/python3.6/site-packages/django/template/base.py", line 835, in _resolve_lookup
    current = current[bit]
KeyError: 'minLength'

During handling of the above exception, another exception occurred:

Traceback (most recent call last):
  File "/home/nsindiso/.local/lib/python3.6/site-packages/django/template/base.py", line 843, in _resolve_lookup
    current = getattr(current, bit)
AttributeError: 'dict' object has no attribute 'minLength'

During handling of the above exception, another exception occurred:

Traceback (most recent call last):
  File "/home/nsindiso/.local/lib/python3.6/site-packages/django/template/base.py", line 849, in _resolve_lookup
    current = current[int(bit)]
ValueError: invalid literal for int() with base 10: 'minLength'

During handling of the above exception, another exception occurred:

Traceback (most recent call last):
  File "/home/nsindiso/.local/lib/python3.6/site-packages/django/template/base.py", line 856, in _resolve_lookup
    (bit, current))  # missing attribute
django.template.base.VariableDoesNotExist: Failed lookup for key [minLength] in {'label': 'SSH Port', 'type': 'int', 'description': 'Port number for SSH connection to device console', 'min': 1, 'max': 65535, 'default': 22, 'required': True}
[2021-04-26 16:31:16.886 DEBUG                    django.template : 878]
Exception while resolving variable 'maxLength' in template 'ysdevices/device_form.html'.
Traceback (most recent call last):
  File "/home/nsindiso/.local/lib/python3.6/site-packages/django/template/base.py", line 835, in _resolve_lookup
    current = current[bit]
KeyError: 'maxLength'

During handling of the above exception, another exception occurred:

Traceback (most recent call last):
  File "/home/nsindiso/.local/lib/python3.6/site-packages/django/template/base.py", line 843, in _resolve_lookup
    current = getattr(current, bit)
AttributeError: 'dict' object has no attribute 'maxLength'

During handling of the above exception, another exception occurred:

Traceback (most recent call last):
  File "/home/nsindiso/.local/lib/python3.6/site-packages/django/template/base.py", line 849, in _resolve_lookup
    current = current[int(bit)]
ValueError: invalid literal for int() with base 10: 'maxLength'

During handling of the above exception, another exception occurred:

Traceback (most recent call last):
  File "/home/nsindiso/.local/lib/python3.6/site-packages/django/template/base.py", line 856, in _resolve_lookup
    (bit, current))  # missing attribute
django.template.base.VariableDoesNotExist: Failed lookup for key [maxLength] in {'label': 'SSH Port', 'type': 'int', 'description': 'Port number for SSH connection to device console', 'min': 1, 'max': 65535, 'default': 22, 'required': True}
[2021-04-26 16:31:16.887 DEBUG                    django.template : 878]
Exception while resolving variable 'step' in template 'ysdevices/device_form.html'.
Traceback (most recent call last):
  File "/home/nsindiso/.local/lib/python3.6/site-packages/django/template/base.py", line 835, in _resolve_lookup
    current = current[bit]
KeyError: 'step'

During handling of the above exception, another exception occurred:

Traceback (most recent call last):
  File "/home/nsindiso/.local/lib/python3.6/site-packages/django/template/base.py", line 843, in _resolve_lookup
    current = getattr(current, bit)
AttributeError: 'dict' object has no attribute 'step'

During handling of the above exception, another exception occurred:

Traceback (most recent call last):
  File "/home/nsindiso/.local/lib/python3.6/site-packages/django/template/base.py", line 849, in _resolve_lookup
    current = current[int(bit)]
ValueError: invalid literal for int() with base 10: 'step'

During handling of the above exception, another exception occurred:

Traceback (most recent call last):
  File "/home/nsindiso/.local/lib/python3.6/site-packages/django/template/base.py", line 856, in _resolve_lookup
    (bit, current))  # missing attribute
django.template.base.VariableDoesNotExist: Failed lookup for key [step] in {'label': 'SSH Port', 'type': 'int', 'description': 'Port number for SSH connection to device console', 'min': 1, 'max': 65535, 'default': 22, 'required': True}
